Workbook

Sheet Summary
A1: Dosa Coffee - Kolkata | B1: Department | C1: 46113 | D1: 46143 | E1: 46174 | F1: 46204 | G1: 46235 | H1: 46266 | I1: 46296 | J1: 46327 | K1: 46357 | L1: 46388 | M1: 46419 | N1: 46447 | O1: FY 2025-26
A2: Food Cost Calculation
A3: Opening Stock | B3: Procurement | C3: ='Ideal Plaza'!B3+'Salt Lake JC -21'!B3+'Forum Mall'!B3+'Lake Town'!B3+'Quest Mall'!B3+'Rosedale Plaza'!B3+'Mani Square Mall'!B3+'Forum Rangoli'!B3+CSC!B3+Jameslong!B3+Technopolis!B3+Santoshpur!B3+'Chinar Park'!B3+'Lake Road'!B3+Kalikapur!B3+'Event Sales'!B3+'Sector 1'!B3 -> 447329 | D3: ='Ideal Plaza'!C3+'Salt Lake JC -21'!C3+'Forum Mall'!C3+'Lake Town'!C3+'Quest Mall'!C3+'Rosedale Plaza'!C3+'Mani Square Mall'!C3+'Forum Rangoli'!C3+CSC!C3+Jameslong!C3+Technopolis!C3+Santoshpur!C3+'Chinar Park'!C3+'Lake Road'!C3+Kalikapur!C3+'Event Sales'!C3+'Sector 1'!C3 -> 526715.46 | E3: ='Ideal Plaza'!D3+'Salt Lake JC -21'!D3+'Forum Mall'!D3+'Lake Town'!D3+'Quest Mall'!D3+'Rosedale Plaza'!D3+'Mani Square Mall'!D3+'Forum Rangoli'!D3+CSC!D3+Jameslong!D3+Technopolis!D3+Santoshpur!D3+'Chinar Park'!D3+'Lake Road'!D3+Kalikapur!D3+'Event Sales'!D3+'Sector 1'!D3 -> 493813.25 | F3: ='Ideal Plaza'!E3+'Salt Lake JC -21'!E3+'Forum Mall'!E3+'Lake Town'!E3+'Quest Mall'!E3+'Rosedale Plaza'!E3+'Mani Square Mall'!E3+'Forum Rangoli'!E3+CSC!E3+Jameslong!E3+Technopolis!E3+Santoshpur!E3+'Chinar Park'!E3+'Lake Road'!E3+Kalikapur!E3+'Event Sales'!E3+'Sector 1'!E3 -> 508615.44 | G3: ='Ideal Plaza'!F3+'Salt Lake JC -21'!F3+'Forum Mall'!F3+'Lake Town'!F3+'Quest Mall'!F3+'Rosedale Plaza'!F3+'Mani Square Mall'!F3+'Forum Rangoli'!F3+CSC!F3+Jameslong!F3+Technopolis!F3+Santoshpur!F3+'Chinar Park'!F3+'Lake Road'!F3+Kalikapur!F3+'Event Sales'!F3+'Sector 1'!F3 -> 427633.73 | H3: ='Ideal Plaza'!G3+'Salt Lake JC -21'!G3+'Forum Mall'!G3+'Lake Town'!G3+'Quest Mall'!G3+'Rosedale Plaza'!G3+'Mani Square Mall'!G3+'Forum Rangoli'!G3+CSC!G3+Jameslong!G3+Technopolis!G3+Santoshpur!G3+'Chinar Park'!G3+'Lake Road'!G3+Kalikapur!G3+'Event Sales'!G3+'Sector 1'!G3 -> 445238.45 | I3: ='Ideal Plaza'!H3+'Salt Lake JC -21'!H3+'Forum Mall'!H3+'Lake Town'!H3+'Quest Mall'!H3+'Rosedale Plaza'!H3+'Mani Square Mall'!H3+'Forum Rangoli'!H3+CSC!H3+Jameslong!H3+Technopolis!H3+Santoshpur!H3+'Chinar Park'!H3+'Lake Road'!H3+Kalikapur!H3+'Event Sales'!H3+'Sector 1'!H3 -> 450578.72 | J3: ='Ideal Plaza'!I3+'Salt Lake JC -21'!I3+'Forum Mall'!I3+'Lake Town'!I3+'Quest Mall'!I3+'Rosedale Plaza'!I3+'Mani Square Mall'!I3+'Forum Rangoli'!I3+CSC!I3+Jameslong!I3+Technopolis!I3+Santoshpur!I3+'Chinar Park'!I3+'Lake Road'!I3+Kalikapur!I3+'Event Sales'!I3+'Sector 1'!I3 -> 0 | ... N3: ='Ideal Plaza'!M3+'Salt Lake JC -21'!M3+'Forum Mall'!M3+'Lake Town'!M3+'Quest Mall'!M3+'Rosedale Plaza'!M3+'Mani Square Mall'!M3+'Forum Rangoli'!M3+CSC!M3+Jameslong!M3+Technopolis!M3+Santoshpur!M3+'Chinar Park'!M3+'Lake Road'!M3+Kalikapur!M3+'Event Sales'!M3+'Sector 1'!M3 -> 0 | R3: ='Central Kitchen - Kolkata'!F6 -> 6907308
A4: Purchases Food (Less Purchase Return) | B4: Procurement | C4: ='Ideal Plaza'!B4+'Salt Lake JC -21'!B4+'Forum Mall'!B4+'Lake Town'!B4+'Quest Mall'!B4+'Rosedale Plaza'!B4+'Mani Square Mall'!B4+'Forum Rangoli'!B4+CSC!B4+Jameslong!B4+Technopolis!B4+Santoshpur!B4+'Chinar Park'!B4+'Lake Road'!B4+Kalikapur!B4+'Event Sales'!B4+'Sector 1'!B4+140608 -> 5564785.3 | D4: ='Ideal Plaza'!C4+'Salt Lake JC -21'!C4+'Forum Mall'!C4+'Lake Town'!C4+'Quest Mall'!C4+'Rosedale Plaza'!C4+'Mani Square Mall'!C4+'Forum Rangoli'!C4+CSC!C4+Jameslong!C4+Technopolis!C4+Santoshpur!C4+'Chinar Park'!C4+'Lake Road'!C4+Kalikapur!C4+'Event Sales'!C4+'Sector 1'!C4+372700 -> 6109164.4 | E4: ='Ideal Plaza'!D4+'Salt Lake JC -21'!D4+'Forum Mall'!D4+'Lake Town'!D4+'Quest Mall'!D4+'Rosedale Plaza'!D4+'Mani Square Mall'!D4+'Forum Rangoli'!D4+CSC!D4+Jameslong!D4+Technopolis!D4+Santoshpur!D4+'Chinar Park'!D4+'Lake Road'!D4+Kalikapur!D4+'Event Sales'!D4+'Sector 1'!D4+122665 -> 6056091.9 | F4: ='Ideal Plaza'!E4+'Salt Lake JC -21'!E4+'Forum Mall'!E4+'Lake Town'!E4+'Quest Mall'!E4+'Rosedale Plaza'!E4+'Mani Square Mall'!E4+'Forum Rangoli'!E4+CSC!E4+Jameslong!E4+Technopolis!E4+Santoshpur!E4+'Chinar Park'!E4+'Lake Road'!E4+Kalikapur!E4+'Event Sales'!E4+'Sector 1'!E4 -> 6114107.9 | G4: ='Ideal Plaza'!F4+'Salt Lake JC -21'!F4+'Forum Mall'!F4+'Lake Town'!F4+'Quest Mall'!F4+'Rosedale Plaza'!F4+'Mani Square Mall'!F4+'Forum Rangoli'!F4+CSC!F4+Jameslong!F4+Technopolis!F4+Santoshpur!F4+'Chinar Park'!F4+'Lake Road'!F4+Kalikapur!F4+'Event Sales'!F4+'Sector 1'!F4+153979 -> 6907307.7 | H4: ='Ideal Plaza'!G4+'Salt Lake JC -21'!G4+'Forum Mall'!G4+'Lake Town'!G4+'Quest Mall'!G4+'Rosedale Plaza'!G4+'Mani Square Mall'!G4+'Forum Rangoli'!G4+CSC!G4+Jameslong!G4+Technopolis!G4+Santoshpur!G4+'Chinar Park'!G4+'Lake Road'!G4+Kalikapur!G4+'Event Sales'!G4+'Sector 1'!G4+79474 -> 6135736.4 | I4: ='Ideal Plaza'!H4+'Salt Lake JC -21'!H4+'Forum Mall'!H4+'Lake Town'!H4+'Quest Mall'!H4+'Rosedale Plaza'!H4+'Mani Square Mall'!H4+'Forum Rangoli'!H4+CSC!H4+Jameslong!H4+Technopolis!H4+Santoshpur!H4+'Chinar Park'!H4+'Lake Road'!H4+Kalikapur!H4+'Event Sales'!H4+'Sector 1'!H4 -> 0 | J4: ='Ideal Plaza'!I4+'Salt Lake JC -21'!I4+'Forum Mall'!I4+'Lake Town'!I4+'Quest Mall'!I4+'Rosedale Plaza'!I4+'Mani Square Mall'!I4+'Forum Rangoli'!I4+CSC!I4+Jameslong!I4+Technopolis!I4+Santoshpur!I4+'Chinar Park'!I4+'Lake Road'!I4+Kalikapur!I4+'Event Sales'!I4+'Sector 1'!I4 -> 0 | K4: ='Ideal Plaza'!J4+'Salt Lake JC -21'!J4+'Forum Mall'!J4+'Lake Town'!J4+'Quest Mall'!J4+'Rosedale Plaza'!J4+'Mani Square Mall'!J4+'Forum Rangoli'!J4+CSC!J4+Jameslong!J4+Technopolis!J4+Santoshpur!J4+'Chinar Park'!J4+'Lake Road'!J4+Kalikapur!J4+'Event Sales'!J4+'Sector 1'!J4 -> 0 | L4: ='Ideal Plaza'!K4+'Salt Lake JC -21'!K4+'Forum Mall'!K4+'Lake Town'!K4+'Quest Mall'!K4+'Rosedale Plaza'!K4+'Mani Square Mall'!K4+'Forum Rangoli'!K4+CSC!K4+Jameslong!K4+Technopolis!K4+Santoshpur!K4+'Chinar Park'!K4+'Lake Road'!K4+Kalikapur!K4+'Event Sales'!K4+'Sector 1'!K4 -> 0 | M4: ='Ideal Plaza'!L4+'Salt Lake JC -21'!L4+'Forum Mall'!L4+'Lake Town'!L4+'Quest Mall'!L4+'Rosedale Plaza'!L4+'Mani Square Mall'!L4+'Forum Rangoli'!L4+CSC!L4+Jameslong!L4+Technopolis!L4+Santoshpur!L4+'Chinar Park'!L4+'Lake Road'!L4+Kalikapur!L4+'Event Sales'!L4+'Sector 1'!L4 -> 0 | N4: ='Ideal Plaza'!M4+'Salt Lake JC -21'!M4+'Forum Mall'!M4+'Lake Town'!M4+'Quest Mall'!M4+'Rosedale Plaza'!M4+'Mani Square Mall'!M4+'Forum Rangoli'!M4+CSC!M4+Jameslong!M4+Technopolis!M4+Santoshpur!M4+'Chinar Park'!M4+'Lake Road'!M4+Kalikapur!M4+'Event Sales'!M4+'Sector 1'!M4 -> 0 | O4: =sum(C4:N4) -> 36887194 | R4: =G4-R3 -> -0.29
A5: Transferred Out | B5: Procurement | C5: ='Ideal Plaza'!B5+'Salt Lake JC -21'!B5+'Forum Mall'!B5+'Lake Town'!B5+'Quest Mall'!B5+'Rosedale Plaza'!B5+'Mani Square Mall'!B5+'Forum Rangoli'!B5+CSC!B5+Jameslong!B5+Technopolis!B5+Santoshpur!B5+'Chinar Park'!B5+'Lake Road'!B5+Kalikapur!B5+'Event Sales'!B5+'Sector 1'!B5 -> 13904.56 | D5: ='Ideal Plaza'!C5+'Salt Lake JC -21'!C5+'Forum Mall'!C5+'Lake Town'!C5+'Quest Mall'!C5+'Rosedale Plaza'!C5+'Mani Square Mall'!C5+'Forum Rangoli'!C5+CSC!C5+Jameslong!C5+Technopolis!C5+Santoshpur!C5+'Chinar Park'!C5+'Lake Road'!C5+Kalikapur!C5+'Event Sales'!C5+'Sector 1'!C5 -> 12778.38 | E5: ='Ideal Plaza'!D5+'Salt Lake JC -21'!D5+'Forum Mall'!D5+'Lake Town'!D5+'Quest Mall'!D5+'Rosedale Plaza'!D5+'Mani Square Mall'!D5+'Forum Rangoli'!D5+CSC!D5+Jameslong!D5+Technopolis!D5+Santoshpur!D5+'Chinar Park'!D5+'Lake Road'!D5+Kalikapur!D5+'Event Sales'!D5+'Sector 1'!D5 -> 7693.46 | F5: ='Ideal Plaza'!E5+'Salt Lake JC -21'!E5+'Forum Mall'!E5+'Lake Town'!E5+'Quest Mall'!E5+'Rosedale Plaza'!E5+'Mani Square Mall'!E5+'Forum Rangoli'!E5+CSC!E5+Jameslong!E5+Technopolis!E5+Santoshpur!E5+'Chinar Park'!E5+'Lake Road'!E5+Kalikapur!E5+'Event Sales'!E5+'Sector 1'!E5 -> 13696.73 | G5: ='Ideal Plaza'!F5+'Salt Lake JC -21'!F5+'Forum Mall'!F5+'Lake Town'!F5+'Quest Mall'!F5+'Rosedale Plaza'!F5+'Mani Square Mall'!F5+'Forum Rangoli'!F5+CSC!F5+Jameslong!F5+Technopolis!F5+Santoshpur!F5+'Chinar Park'!F5+'Lake Road'!F5+Kalikapur!F5+'Event Sales'!F5+'Sector 1'!F5 -> 12730.2 | H5: ='Ideal Plaza'!G5+'Salt Lake JC -21'!G5+'Forum Mall'!G5+'Lake Town'!G5+'Quest Mall'!G5+'Rosedale Plaza'!G5+'Mani Square Mall'!G5+'Forum Rangoli'!G5+CSC!G5+Jameslong!G5+Technopolis!G5+Santoshpur!G5+'Chinar Park'!G5+'Lake Road'!G5+Kalikapur!G5+'Event Sales'!G5+'Sector 1'!G5 -> 18574.71 | I5: ='Ideal Plaza'!H5+'Salt Lake JC -21'!H5+'Forum Mall'!H5+'Lake Town'!H5+'Quest Mall'!H5+'Rosedale Plaza'!H5+'Mani Square Mall'!H5+'Forum Rangoli'!H5+CSC!H5+Jameslong!H5+Technopolis!H5+Santoshpur!H5+'Chinar Park'!H5+'Lake Road'!H5+Kalikapur!H5+'Event Sales'!H5+'Sector 1'!H5 -> 0 | J5: ='Ideal Plaza'!I5+'Salt Lake JC -21'!I5+'Forum Mall'!I5+'Lake Town'!I5+'Quest Mall'!I5+'Rosedale Plaza'!I5+'Mani Square Mall'!I5+'Forum Rangoli'!I5+CSC!I5+Jameslong!I5+Technopolis!I5+Santoshpur!I5+'Chinar Park'!I5+'Lake Road'!I5+Kalikapur!I5+'Event Sales'!I5+'Sector 1'!I5 -> 0 | ... N5: ='Ideal Plaza'!M5+'Salt Lake JC -21'!M5+'Forum Mall'!M5+'Lake Town'!M5+'Quest Mall'!M5+'Rosedale Plaza'!M5+'Mani Square Mall'!M5+'Forum Rangoli'!M5+CSC!M5+Jameslong!M5+Technopolis!M5+Santoshpur!M5+'Chinar Park'!M5+'Lake Road'!M5+Kalikapur!M5+'Event Sales'!M5+'Sector 1'!M5 -> 0 | O5: =sum(C5:N5) -> 79378.04
A6: Wastage & Date Expired | B6: Procurement | C6: ='Ideal Plaza'!B6+'Salt Lake JC -21'!B6+'Forum Mall'!B6+'Lake Town'!B6+'Quest Mall'!B6+'Rosedale Plaza'!B6+'Mani Square Mall'!B6+'Forum Rangoli'!B6+CSC!B6+Jameslong!B6+Technopolis!B6+Santoshpur!B6+'Chinar Park'!B6+'Lake Road'!B6+Kalikapur!B6+'Event Sales'!B6+'Sector 1'!B6 -> 190296.11 | D6: ='Ideal Plaza'!C6+'Salt Lake JC -21'!C6+'Forum Mall'!C6+'Lake Town'!C6+'Quest Mall'!C6+'Rosedale Plaza'!C6+'Mani Square Mall'!C6+'Forum Rangoli'!C6+CSC!C6+Jameslong!C6+Technopolis!C6+Santoshpur!C6+'Chinar Park'!C6+'Lake Road'!C6+Kalikapur!C6+'Event Sales'!C6+'Sector 1'!C6 -> 204666.46 | E6: ='Ideal Plaza'!D6+'Salt Lake JC -21'!D6+'Forum Mall'!D6+'Lake Town'!D6+'Quest Mall'!D6+'Rosedale Plaza'!D6+'Mani Square Mall'!D6+'Forum Rangoli'!D6+CSC!D6+Jameslong!D6+Technopolis!D6+Santoshpur!D6+'Chinar Park'!D6+'Lake Road'!D6+Kalikapur!D6+'Event Sales'!D6+'Sector 1'!D6 -> 205928.27 | F6: ='Ideal Plaza'!E6+'Salt Lake JC -21'!E6+'Forum Mall'!E6+'Lake Town'!E6+'Quest Mall'!E6+'Rosedale Plaza'!E6+'Mani Square Mall'!E6+'Forum Rangoli'!E6+CSC!E6+Jameslong!E6+Technopolis!E6+Santoshpur!E6+'Chinar Park'!E6+'Lake Road'!E6+Kalikapur!E6+'Event Sales'!E6+'Sector 1'!E6 -> 220814.31 | G6: ='Ideal Plaza'!F6+'Salt Lake JC -21'!F6+'Forum Mall'!F6+'Lake Town'!F6+'Quest Mall'!F6+'Rosedale Plaza'!F6+'Mani Square Mall'!F6+'Forum Rangoli'!F6+CSC!F6+Jameslong!F6+Technopolis!F6+Santoshpur!F6+'Chinar Park'!F6+'Lake Road'!F6+Kalikapur!F6+'Event Sales'!F6+'Sector 1'!F6 -> 281646.38 | H6: ='Ideal Plaza'!G6+'Salt Lake JC -21'!G6+'Forum Mall'!G6+'Lake Town'!G6+'Quest Mall'!G6+'Rosedale Plaza'!G6+'Mani Square Mall'!G6+'Forum Rangoli'!G6+CSC!G6+Jameslong!G6+Technopolis!G6+Santoshpur!G6+'Chinar Park'!G6+'Lake Road'!G6+Kalikapur!G6+'Event Sales'!G6+'Sector 1'!G6 -> 301691.69 | I6: ='Ideal Plaza'!H6+'Salt Lake JC -21'!H6+'Forum Mall'!H6+'Lake Town'!H6+'Quest Mall'!H6+'Rosedale Plaza'!H6+'Mani Square Mall'!H6+'Forum Rangoli'!H6+CSC!H6+Jameslong!H6+Technopolis!H6+Santoshpur!H6+'Chinar Park'!H6+'Lake Road'!H6+Kalikapur!H6+'Event Sales'!H6+'Sector 1'!H6 -> 0 | J6: ='Ideal Plaza'!I6+'Salt Lake JC -21'!I6+'Forum Mall'!I6+'Lake Town'!I6+'Quest Mall'!I6+'Rosedale Plaza'!I6+'Mani Square Mall'!I6+'Forum Rangoli'!I6+CSC!I6+Jameslong!I6+Technopolis!I6+Santoshpur!I6+'Chinar Park'!I6+'Lake Road'!I6+Kalikapur!I6+'Event Sales'!I6+'Sector 1'!I6 -> 0 | ... N6: ='Ideal Plaza'!M6+'Salt Lake JC -21'!M6+'Forum Mall'!M6+'Lake Town'!M6+'Quest Mall'!M6+'Rosedale Plaza'!M6+'Mani Square Mall'!M6+'Forum Rangoli'!M6+CSC!M6+Jameslong!M6+Technopolis!M6+Santoshpur!M6+'Chinar Park'!M6+'Lake Road'!M6+Kalikapur!M6+'Event Sales'!M6+'Sector 1'!M6 -> 0 | O6: =sum(C6:N6) -> 1405043.2
A7: Closing Stock | B7: Procurement | C7: ='Ideal Plaza'!B7+'Salt Lake JC -21'!B7+'Forum Mall'!B7+'Lake Town'!B7+'Quest Mall'!B7+'Rosedale Plaza'!B7+'Mani Square Mall'!B7+'Forum Rangoli'!B7+CSC!B7+Jameslong!B7+Technopolis!B7+Santoshpur!B7+'Chinar Park'!B7+'Lake Road'!B7+Kalikapur!B7+'Event Sales'!B7+'Sector 1'!B7 -> 526715.46 | D7: ='Ideal Plaza'!C7+'Salt Lake JC -21'!C7+'Forum Mall'!C7+'Lake Town'!C7+'Quest Mall'!C7+'Rosedale Plaza'!C7+'Mani Square Mall'!C7+'Forum Rangoli'!C7+CSC!C7+Jameslong!C7+Technopolis!C7+Santoshpur!C7+'Chinar Park'!C7+'Lake Road'!C7+Kalikapur!C7+'Event Sales'!C7+'Sector 1'!C7 -> 493813.25 | E7: ='Ideal Plaza'!D7+'Salt Lake JC -21'!D7+'Forum Mall'!D7+'Lake Town'!D7+'Quest Mall'!D7+'Rosedale Plaza'!D7+'Mani Square Mall'!D7+'Forum Rangoli'!D7+CSC!D7+Jameslong!D7+Technopolis!D7+Santoshpur!D7+'Chinar Park'!D7+'Lake Road'!D7+Kalikapur!D7+'Event Sales'!D7+'Sector 1'!D7 -> 508615.44 | F7: ='Ideal Plaza'!E7+'Salt Lake JC -21'!E7+'Forum Mall'!E7+'Lake Town'!E7+'Quest Mall'!E7+'Rosedale Plaza'!E7+'Mani Square Mall'!E7+'Forum Rangoli'!E7+CSC!E7+Jameslong!E7+Technopolis!E7+Santoshpur!E7+'Chinar Park'!E7+'Lake Road'!E7+Kalikapur!E7+'Event Sales'!E7+'Sector 1'!E7 -> 427633.73 | G7: ='Ideal Plaza'!F7+'Salt Lake JC -21'!F7+'Forum Mall'!F7+'Lake Town'!F7+'Quest Mall'!F7+'Rosedale Plaza'!F7+'Mani Square Mall'!F7+'Forum Rangoli'!F7+CSC!F7+Jameslong!F7+Technopolis!F7+Santoshpur!F7+'Chinar Park'!F7+'Lake Road'!F7+Kalikapur!F7+'Event Sales'!F7+'Sector 1'!F7 -> 445238.45 | H7: ='Ideal Plaza'!G7+'Salt Lake JC -21'!G7+'Forum Mall'!G7+'Lake Town'!G7+'Quest Mall'!G7+'Rosedale Plaza'!G7+'Mani Square Mall'!G7+'Forum Rangoli'!G7+CSC!G7+Jameslong!G7+Technopolis!G7+Santoshpur!G7+'Chinar Park'!G7+'Lake Road'!G7+Kalikapur!G7+'Event Sales'!G7+'Sector 1'!G7 -> 450578.72 | I7: ='Ideal Plaza'!H7+'Salt Lake JC -21'!H7+'Forum Mall'!H7+'Lake Town'!H7+'Quest Mall'!H7+'Rosedale Plaza'!H7+'Mani Square Mall'!H7+'Forum Rangoli'!H7+CSC!H7+Jameslong!H7+Technopolis!H7+Santoshpur!H7+'Chinar Park'!H7+'Lake Road'!H7+Kalikapur!H7+'Event Sales'!H7+'Sector 1'!H7 -> 0 | J7: ='Ideal Plaza'!I7+'Salt Lake JC -21'!I7+'Forum Mall'!I7+'Lake Town'!I7+'Quest Mall'!I7+'Rosedale Plaza'!I7+'Mani Square Mall'!I7+'Forum Rangoli'!I7+CSC!I7+Jameslong!I7+Technopolis!I7+Santoshpur!I7+'Chinar Park'!I7+'Lake Road'!I7+Kalikapur!I7+'Event Sales'!I7+'Sector 1'!I7 -> 0 | ... N7: ='Ideal Plaza'!M7+'Salt Lake JC -21'!M7+'Forum Mall'!M7+'Lake Town'!M7+'Quest Mall'!M7+'Rosedale Plaza'!M7+'Mani Square Mall'!M7+'Forum Rangoli'!M7+CSC!M7+Jameslong!M7+Technopolis!M7+Santoshpur!M7+'Chinar Park'!M7+'Lake Road'!M7+Kalikapur!M7+'Event Sales'!M7+'Sector 1'!M7 -> 0 | O7: =sum(C7:N7) -> 2852595
A9: Gross Revenue | B9: Operation | C9: ='Ideal Plaza'!B9+'Salt Lake JC -21'!B9+'Forum Mall'!B9+'Lake Town'!B9+'Quest Mall'!B9+'Rosedale Plaza'!B9+'Mani Square Mall'!B9+'Forum Rangoli'!B9+CSC!B9+Jameslong!B9+Technopolis!B9+Santoshpur!B9+'Chinar Park'!B9+'Lake Road'!B9+Kalikapur!B9+'Event Sales'!B9+'Sector 1'!B9 -> 23538283 | D9: ='Ideal Plaza'!C9+'Salt Lake JC -21'!C9+'Forum Mall'!C9+'Lake Town'!C9+'Quest Mall'!C9+'Rosedale Plaza'!C9+'Mani Square Mall'!C9+'Forum Rangoli'!C9+CSC!C9+Jameslong!C9+Technopolis!C9+Santoshpur!C9+'Chinar Park'!C9+'Lake Road'!C9+Kalikapur!C9+'Event Sales'!C9+'Sector 1'!C9 -> 26036501 | E9: ='Ideal Plaza'!D9+'Salt Lake JC -21'!D9+'Forum Mall'!D9+'Lake Town'!D9+'Quest Mall'!D9+'Rosedale Plaza'!D9+'Mani Square Mall'!D9+'Forum Rangoli'!D9+CSC!D9+Jameslong!D9+Technopolis!D9+Santoshpur!D9+'Chinar Park'!D9+'Lake Road'!D9+Kalikapur!D9+'Event Sales'!D9+'Sector 1'!D9 -> 24955324 | F9: ='Ideal Plaza'!E9+'Salt Lake JC -21'!E9+'Forum Mall'!E9+'Lake Town'!E9+'Quest Mall'!E9+'Rosedale Plaza'!E9+'Mani Square Mall'!E9+'Forum Rangoli'!E9+CSC!E9+Jameslong!E9+Technopolis!E9+Santoshpur!E9+'Chinar Park'!E9+'Lake Road'!E9+Kalikapur!E9+'Event Sales'!E9+'Sector 1'!E9 -> 25713135 | G9: ='Ideal Plaza'!F9+'Salt Lake JC -21'!F9+'Forum Mall'!F9+'Lake Town'!F9+'Quest Mall'!F9+'Rosedale Plaza'!F9+'Mani Square Mall'!F9+'Forum Rangoli'!F9+CSC!F9+Jameslong!F9+Technopolis!F9+Santoshpur!F9+'Chinar Park'!F9+'Lake Road'!F9+Kalikapur!F9+'Event Sales'!F9+'Sector 1'!F9 -> 27975795 | H9: ='Ideal Plaza'!G9+'Salt Lake JC -21'!G9+'Forum Mall'!G9+'Lake Town'!G9+'Quest Mall'!G9+'Rosedale Plaza'!G9+'Mani Square Mall'!G9+'Forum Rangoli'!G9+CSC!G9+Jameslong!G9+Technopolis!G9+Santoshpur!G9+'Chinar Park'!G9+'Lake Road'!G9+Kalikapur!G9+'Event Sales'!G9+'Sector 1'!G9 -> 25745713 | I9: ='Ideal Plaza'!H9+'Salt Lake JC -21'!H9+'Forum Mall'!H9+'Lake Town'!H9+'Quest Mall'!H9+'Rosedale Plaza'!H9+'Mani Square Mall'!H9+'Forum Rangoli'!H9+CSC!H9+Jameslong!H9+Technopolis!H9+Santoshpur!H9+'Chinar Park'!H9+'Lake Road'!H9+Kalikapur!H9+'Event Sales'!H9+'Sector 1'!H9 -> 0 | J9: ='Ideal Plaza'!I9+'Salt Lake JC -21'!I9+'Forum Mall'!I9+'Lake Town'!I9+'Quest Mall'!I9+'Rosedale Plaza'!I9+'Mani Square Mall'!I9+'Forum Rangoli'!I9+CSC!I9+Jameslong!I9+Technopolis!I9+Santoshpur!I9+'Chinar Park'!I9+'Lake Road'!I9+Kalikapur!I9+'Event Sales'!I9+'Sector 1'!I9 -> 0 | ... N9: ='Ideal Plaza'!M9+'Salt Lake JC -21'!M9+'Forum Mall'!M9+'Lake Town'!M9+'Quest Mall'!M9+'Rosedale Plaza'!M9+'Mani Square Mall'!M9+'Forum Rangoli'!M9+CSC!M9+Jameslong!M9+Technopolis!M9+Santoshpur!M9+'Chinar Park'!M9+'Lake Road'!M9+Kalikapur!M9+'Event Sales'!M9+'Sector 1'!M9 -> 0 | O9: =+SUM(C9:N9) -> 1.5396475e+08
A10: Catering & Fairs | B10: Operation | C10: ='Ideal Plaza'!B10+'Salt Lake JC -21'!B10+'Forum Mall'!B10+'Lake Town'!B10+'Quest Mall'!B10+'Rosedale Plaza'!B10+'Mani Square Mall'!B10+'Forum Rangoli'!B10+CSC!B10+Jameslong!B10+Technopolis!B10+Santoshpur!B10+'Chinar Park'!B10+'Lake Road'!B10+Kalikapur!B10+'Event Sales'!B10+'Sector 1'!B10 -> 0 | D10: ='Ideal Plaza'!C10+'Salt Lake JC -21'!C10+'Forum Mall'!C10+'Lake Town'!C10+'Quest Mall'!C10+'Rosedale Plaza'!C10+'Mani Square Mall'!C10+'Forum Rangoli'!C10+CSC!C10+Jameslong!C10+Technopolis!C10+Santoshpur!C10+'Chinar Park'!C10+'Lake Road'!C10+Kalikapur!C10+'Event Sales'!C10+'Sector 1'!C10 -> 0 | E10: ='Ideal Plaza'!D10+'Salt Lake JC -21'!D10+'Forum Mall'!D10+'Lake Town'!D10+'Quest Mall'!D10+'Rosedale Plaza'!D10+'Mani Square Mall'!D10+'Forum Rangoli'!D10+CSC!D10+Jameslong!D10+Technopolis!D10+Santoshpur!D10+'Chinar Park'!D10+'Lake Road'!D10+Kalikapur!D10+'Event Sales'!D10+'Sector 1'!D10 -> 0 | F10: ='Ideal Plaza'!E10+'Salt Lake JC -21'!E10+'Forum Mall'!E10+'Lake Town'!E10+'Quest Mall'!E10+'Rosedale Plaza'!E10+'Mani Square Mall'!E10+'Forum Rangoli'!E10+CSC!E10+Jameslong!E10+Technopolis!E10+Santoshpur!E10+'Chinar Park'!E10+'Lake Road'!E10+Kalikapur!E10+'Event Sales'!E10+'Sector 1'!E10 -> 0 | G10: ='Ideal Plaza'!F10+'Salt Lake JC -21'!F10+'Forum Mall'!F10+'Lake Town'!F10+'Quest Mall'!F10+'Rosedale Plaza'!F10+'Mani Square Mall'!F10+'Forum Rangoli'!F10+CSC!F10+Jameslong!F10+Technopolis!F10+Santoshpur!F10+'Chinar Park'!F10+'Lake Road'!F10+Kalikapur!F10+'Event Sales'!F10+'Sector 1'!F10 -> 0 | H10: ='Ideal Plaza'!G10+'Salt Lake JC -21'!G10+'Forum Mall'!G10+'Lake Town'!G10+'Quest Mall'!G10+'Rosedale Plaza'!G10+'Mani Square Mall'!G10+'Forum Rangoli'!G10+CSC!G10+Jameslong!G10+Technopolis!G10+Santoshpur!G10+'Chinar Park'!G10+'Lake Road'!G10+Kalikapur!G10+'Event Sales'!G10+'Sector 1'!G10 -> 0 | I10: ='Ideal Plaza'!H10+'Salt Lake JC -21'!H10+'Forum Mall'!H10+'Lake Town'!H10+'Quest Mall'!H10+'Rosedale Plaza'!H10+'Mani Square Mall'!H10+'Forum Rangoli'!H10+CSC!H10+Jameslong!H10+Technopolis!H10+Santoshpur!H10+'Chinar Park'!H10+'Lake Road'!H10+Kalikapur!H10+'Event Sales'!H10+'Sector 1'!H10 -> 0 | J10: ='Ideal Plaza'!I10+'Salt Lake JC -21'!I10+'Forum Mall'!I10+'Lake Town'!I10+'Quest Mall'!I10+'Rosedale Plaza'!I10+'Mani Square Mall'!I10+'Forum Rangoli'!I10+CSC!I10+Jameslong!I10+Technopolis!I10+Santoshpur!I10+'Chinar Park'!I10+'Lake Road'!I10+Kalikapur!I10+'Event Sales'!I10+'Sector 1'!I10 -> 0 | ... N10: ='Ideal Plaza'!M10+'Salt Lake JC -21'!M10+'Forum Mall'!M10+'Lake Town'!M10+'Quest Mall'!M10+'Rosedale Plaza'!M10+'Mani Square Mall'!M10+'Forum Rangoli'!M10+CSC!M10+Jameslong!M10+Technopolis!M10+Santoshpur!M10+'Chinar Park'!M10+'Lake Road'!M10+Kalikapur!M10+'Event Sales'!M10+'Sector 1'!M10 -> 0 | O10: =+SUM(C10:N10) -> 0
A11: Less Tax | B11: Operation | C11: ='Ideal Plaza'!B11+'Salt Lake JC -21'!B11+'Forum Mall'!B11+'Lake Town'!B11+'Quest Mall'!B11+'Rosedale Plaza'!B11+'Mani Square Mall'!B11+'Forum Rangoli'!B11+CSC!B11+Jameslong!B11+Technopolis!B11+Santoshpur!B11+'Chinar Park'!B11+'Lake Road'!B11+Kalikapur!B11+'Event Sales'!B11+'Sector 1'!B11 -> 1120870.6 | D11: ='Ideal Plaza'!C11+'Salt Lake JC -21'!C11+'Forum Mall'!C11+'Lake Town'!C11+'Quest Mall'!C11+'Rosedale Plaza'!C11+'Mani Square Mall'!C11+'Forum Rangoli'!C11+CSC!C11+Jameslong!C11+Technopolis!C11+Santoshpur!C11+'Chinar Park'!C11+'Lake Road'!C11+Kalikapur!C11+'Event Sales'!C11+'Sector 1'!C11 -> 1239833.4 | E11: ='Ideal Plaza'!D11+'Salt Lake JC -21'!D11+'Forum Mall'!D11+'Lake Town'!D11+'Quest Mall'!D11+'Rosedale Plaza'!D11+'Mani Square Mall'!D11+'Forum Rangoli'!D11+CSC!D11+Jameslong!D11+Technopolis!D11+Santoshpur!D11+'Chinar Park'!D11+'Lake Road'!D11+Kalikapur!D11+'Event Sales'!D11+'Sector 1'!D11 -> 1188348.8 | F11: ='Ideal Plaza'!E11+'Salt Lake JC -21'!E11+'Forum Mall'!E11+'Lake Town'!E11+'Quest Mall'!E11+'Rosedale Plaza'!E11+'Mani Square Mall'!E11+'Forum Rangoli'!E11+CSC!E11+Jameslong!E11+Technopolis!E11+Santoshpur!E11+'Chinar Park'!E11+'Lake Road'!E11+Kalikapur!E11+'Event Sales'!E11+'Sector 1'!E11 -> 1224435 | G11: ='Ideal Plaza'!F11+'Salt Lake JC -21'!F11+'Forum Mall'!F11+'Lake Town'!F11+'Quest Mall'!F11+'Rosedale Plaza'!F11+'Mani Square Mall'!F11+'Forum Rangoli'!F11+CSC!F11+Jameslong!F11+Technopolis!F11+Santoshpur!F11+'Chinar Park'!F11+'Lake Road'!F11+Kalikapur!F11+'Event Sales'!F11+'Sector 1'!F11 -> 1332180.7 | H11: ='Ideal Plaza'!G11+'Salt Lake JC -21'!G11+'Forum Mall'!G11+'Lake Town'!G11+'Quest Mall'!G11+'Rosedale Plaza'!G11+'Mani Square Mall'!G11+'Forum Rangoli'!G11+CSC!G11+Jameslong!G11+Technopolis!G11+Santoshpur!G11+'Chinar Park'!G11+'Lake Road'!G11+Kalikapur!G11+'Event Sales'!G11+'Sector 1'!G11 -> 1225986.3 | I11: ='Ideal Plaza'!H11+'Salt Lake JC -21'!H11+'Forum Mall'!H11+'Lake Town'!H11+'Quest Mall'!H11+'Rosedale Plaza'!H11+'Mani Square Mall'!H11+'Forum Rangoli'!H11+CSC!H11+Jameslong!H11+Technopolis!H11+Santoshpur!H11+'Chinar Park'!H11+'Lake Road'!H11+Kalikapur!H11+'Event Sales'!H11+'Sector 1'!H11 -> 0 | J11: ='Ideal Plaza'!I11+'Salt Lake JC -21'!I11+'Forum Mall'!I11+'Lake Town'!I11+'Quest Mall'!I11+'Rosedale Plaza'!I11+'Mani Square Mall'!I11+'Forum Rangoli'!I11+CSC!I11+Jameslong!I11+Technopolis!I11+Santoshpur!I11+'Chinar Park'!I11+'Lake Road'!I11+Kalikapur!I11+'Event Sales'!I11+'Sector 1'!I11 -> 0 | ... N11: ='Ideal Plaza'!M11+'Salt Lake JC -21'!M11+'Forum Mall'!M11+'Lake Town'!M11+'Quest Mall'!M11+'Rosedale Plaza'!M11+'Mani Square Mall'!M11+'Forum Rangoli'!M11+CSC!M11+Jameslong!M11+Technopolis!M11+Santoshpur!M11+'Chinar Park'!M11+'Lake Road'!M11+Kalikapur!M11+'Event Sales'!M11+'Sector 1'!M11 -> 0 | O11: =+SUM(C11:N11) -> 7331654.8
A12: Less Commission | B12: Operation | C12: ='Ideal Plaza'!B12+'Salt Lake JC -21'!B12+'Forum Mall'!B12+'Lake Town'!B12+'Quest Mall'!B12+'Rosedale Plaza'!B12+'Mani Square Mall'!B12+'Forum Rangoli'!B12+CSC!B12+Jameslong!B12+Technopolis!B12+Santoshpur!B12+'Chinar Park'!B12+'Lake Road'!B12+Kalikapur!B12+'Event Sales'!B12+'Sector 1'!B12 -> 2078483.9 | D12: ='Ideal Plaza'!C12+'Salt Lake JC -21'!C12+'Forum Mall'!C12+'Lake Town'!C12+'Quest Mall'!C12+'Rosedale Plaza'!C12+'Mani Square Mall'!C12+'Forum Rangoli'!C12+CSC!C12+Jameslong!C12+Technopolis!C12+Santoshpur!C12+'Chinar Park'!C12+'Lake Road'!C12+Kalikapur!C12+'Event Sales'!C12+'Sector 1'!C12 -> 2248672.2 | E12: ='Ideal Plaza'!D12+'Salt Lake JC -21'!D12+'Forum Mall'!D12+'Lake Town'!D12+'Quest Mall'!D12+'Rosedale Plaza'!D12+'Mani Square Mall'!D12+'Forum Rangoli'!D12+CSC!D12+Jameslong!D12+Technopolis!D12+Santoshpur!D12+'Chinar Park'!D12+'Lake Road'!D12+Kalikapur!D12+'Event Sales'!D12+'Sector 1'!D12 -> 2098372.9 | F12: ='Ideal Plaza'!E12+'Salt Lake JC -21'!E12+'Forum Mall'!E12+'Lake Town'!E12+'Quest Mall'!E12+'Rosedale Plaza'!E12+'Mani Square Mall'!E12+'Forum Rangoli'!E12+CSC!E12+Jameslong!E12+Technopolis!E12+Santoshpur!E12+'Chinar Park'!E12+'Lake Road'!E12+Kalikapur!E12+'Event Sales'!E12+'Sector 1'!E12 -> 2312388.2 | G12: ='Ideal Plaza'!F12+'Salt Lake JC -21'!F12+'Forum Mall'!F12+'Lake Town'!F12+'Quest Mall'!F12+'Rosedale Plaza'!F12+'Mani Square Mall'!F12+'Forum Rangoli'!F12+CSC!F12+Jameslong!F12+Technopolis!F12+Santoshpur!F12+'Chinar Park'!F12+'Lake Road'!F12+Kalikapur!F12+'Event Sales'!F12+'Sector 1'!F12 -> 2501416 | H12: ='Ideal Plaza'!G12+'Salt Lake JC -21'!G12+'Forum Mall'!G12+'Lake Town'!G12+'Quest Mall'!G12+'Rosedale Plaza'!G12+'Mani Square Mall'!G12+'Forum Rangoli'!G12+CSC!G12+Jameslong!G12+Technopolis!G12+Santoshpur!G12+'Chinar Park'!G12+'Lake Road'!G12+Kalikapur!G12+'Event Sales'!G12+'Sector 1'!G12 -> 2325503.8 | I12: ='Ideal Plaza'!H12+'Salt Lake JC -21'!H12+'Forum Mall'!H12+'Lake Town'!H12+'Quest Mall'!H12+'Rosedale Plaza'!H12+'Mani Square Mall'!H12+'Forum Rangoli'!H12+CSC!H12+Jameslong!H12+Technopolis!H12+Santoshpur!H12+'Chinar Park'!H12+'Lake Road'!H12+Kalikapur!H12+'Event Sales'!H12+'Sector 1'!H12 -> 0 | J12: ='Ideal Plaza'!I12+'Salt Lake JC -21'!I12+'Forum Mall'!I12+'Lake Town'!I12+'Quest Mall'!I12+'Rosedale Plaza'!I12+'Mani Square Mall'!I12+'Forum Rangoli'!I12+CSC!I12+Jameslong!I12+Technopolis!I12+Santoshpur!I12+'Chinar Park'!I12+'Lake Road'!I12+Kalikapur!I12+'Event Sales'!I12+'Sector 1'!I12 -> 0 | ... N12: ='Ideal Plaza'!M12+'Salt Lake JC -21'!M12+'Forum Mall'!M12+'Lake Town'!M12+'Quest Mall'!M12+'Rosedale Plaza'!M12+'Mani Square Mall'!M12+'Forum Rangoli'!M12+CSC!M12+Jameslong!M12+Technopolis!M12+Santoshpur!M12+'Chinar Park'!M12+'Lake Road'!M12+Kalikapur!M12+'Event Sales'!M12+'Sector 1'!M12 -> 0 | O12: =+SUM(C12:N12) -> 13564837
A13: Commission % | C13: =C12/C9 -> 0.088302274 | D13: =D12/D9 -> 0.086366145 | E13: =E12/E9 -> 0.08408518 | F13: =F12/F9 -> 0.089930231 | G13: =G12/G9 -> 0.089413578 | H13: =H12/H9 -> 0.090325866 | I13: =I12/I9 -> #DIV/0! | J13: =J12/J9 -> #DIV/0! | ... N13: =N12/N9 -> #DIV/0!
A14: Net Revenues from F&B Sales | C14: =C9+C10-C11-C12 -> 20338929 | D14: =D9+D10-D11-D12 -> 22547995 | E14: =E9+E10-E11-E12 -> 21668602 | F14: =F9+F10-F11-F12 -> 22176312 | G14: =G9+G10-G11-G12 -> 24142199 | H14: =H9+H10-H11-H12 -> 22194223 | I14: =I9+I10-I11-I12 -> 0 | J14: =J9+J10-J11-J12 -> 0 | ... N14: =N9+N10-N11-N12 -> 0 | O14: =sum(C14:N14) -> 1.3306826e+08 | P14: =O14/$O$14 -> 1
A15: F&B Cost | B15: Operation | C15: =C3+C4-C5-C7 -> 5471494.3 | D15: =D3+D4-D5-D7 -> 6129288.3 | E15: =E3+E4-E5-E7 -> 6033596.2 | F15: =F3+F4-F5-F7 -> 6181392.9 | G15: =G3+G4-G5-G7 -> 6876972.8 | H15: =H3+H4-H5-H7 -> 6111821.4 | I15: =I3+I4-I5-I7 -> 450578.72 | J15: =J3+J4-J5-J7 -> 0 | ... N15: =N3+N4-N5-N7 -> 0 | O15: =sum(C15:N15) -> 37255145 | P15: =O15/$O$14 -> 0.27997018
A16: Electricity | B16: Operation | C16: ='Ideal Plaza'!B15+'Salt Lake JC -21'!B15+'Forum Mall'!B15+'Lake Town'!B15+'Quest Mall'!B15+'Rosedale Plaza'!B15+'Mani Square Mall'!B15+'Forum Rangoli'!B15+CSC!B17+Jameslong!B15+Technopolis!B15+Santoshpur!B15+'Chinar Park'!B15+'Lake Road'!B15+Kalikapur!B15+'Event Sales'!B15+'Sector 1'!B15 -> 885727.04 | D16: ='Ideal Plaza'!C15+'Salt Lake JC -21'!C15+'Forum Mall'!C15+'Lake Town'!C15+'Quest Mall'!C15+'Rosedale Plaza'!C15+'Mani Square Mall'!C15+'Forum Rangoli'!C15+CSC!C15+Jameslong!C15+Technopolis!C15+Santoshpur!C15+'Chinar Park'!C15+'Lake Road'!C15+Kalikapur!C15+'Event Sales'!C15+'Sector 1'!C15 -> 959247.54 | E16: ='Ideal Plaza'!D15+'Salt Lake JC -21'!D15+'Forum Mall'!D15+'Lake Town'!D15+'Quest Mall'!D15+'Rosedale Plaza'!D15+'Mani Square Mall'!D15+'Forum Rangoli'!D15+CSC!D15+Jameslong!D15+Technopolis!D15+Santoshpur!D15+'Chinar Park'!D15+'Lake Road'!D15+Kalikapur!D15+'Event Sales'!D15+'Sector 1'!D15 -> 925105.63 | F16: ='Ideal Plaza'!E15+'Salt Lake JC -21'!E15+'Forum Mall'!E15+'Lake Town'!E15+'Quest Mall'!E15+'Rosedale Plaza'!E15+'Mani Square Mall'!E15+'Forum Rangoli'!E15+CSC!E15+Jameslong!E15+Technopolis!E15+Santoshpur!E15+'Chinar Park'!E15+'Lake Road'!E15+Kalikapur!E15+'Event Sales'!E15+'Sector 1'!E15 -> 909978.12 | G16: ='Ideal Plaza'!F15+'Salt Lake JC -21'!F15+'Forum Mall'!F15+'Lake Town'!F15+'Quest Mall'!F15+'Rosedale Plaza'!F15+'Mani Square Mall'!F15+'Forum Rangoli'!F15+CSC!F15+Jameslong!F15+Technopolis!F15+Santoshpur!F15+'Chinar Park'!F15+'Lake Road'!F15+Kalikapur!F15+'Event Sales'!F15+'Sector 1'!F15 -> 920092.26 | H16: ='Ideal Plaza'!G15+'Salt Lake JC -21'!G15+'Forum Mall'!G15+'Lake Town'!G15+'Quest Mall'!G15+'Rosedale Plaza'!G15+'Mani Square Mall'!G15+'Forum Rangoli'!G15+CSC!G15+Jameslong!G15+Technopolis!G15+Santoshpur!G15+'Chinar Park'!G15+'Lake Road'!G15+Kalikapur!G15+'Event Sales'!G15+'Sector 1'!G15 -> 895687.64 | I16: ='Ideal Plaza'!H15+'Salt Lake JC -21'!H15+'Forum Mall'!H15+'Lake Town'!H15+'Quest Mall'!H15+'Rosedale Plaza'!H15+'Mani Square Mall'!H15+'Forum Rangoli'!H15+CSC!H15+Jameslong!H15+Technopolis!H15+Santoshpur!H15+'Chinar Park'!H15+'Lake Road'!H15+Kalikapur!H15+'Event Sales'!H15+'Sector 1'!H15 -> 0 | J16: ='Ideal Plaza'!I15+'Salt Lake JC -21'!I15+'Forum Mall'!I15+'Lake Town'!I15+'Quest Mall'!I15+'Rosedale Plaza'!I15+'Mani Square Mall'!I15+'Forum Rangoli'!I15+CSC!I15+Jameslong!I15+Technopolis!I15+Santoshpur!I15+'Chinar Park'!I15+'Lake Road'!I15+Kalikapur!I15+'Event Sales'!I15+'Sector 1'!I15 -> 0 | K16: ='Ideal Plaza'!J15+'Salt Lake JC -21'!J15+'Forum Mall'!J15+'Lake Town'!J15+'Quest Mall'!J15+'Rosedale Plaza'!J15+'Mani Square Mall'!J15+'Forum Rangoli'!J15+CSC!J15+Jameslong!J15+Technopolis!J15+Santoshpur!J15+'Chinar Park'!J15+'Lake Road'!J15+Kalikapur!J15+'Event Sales'!J15+'Sector 1'!J15 -> 0 | ... N16: ='Ideal Plaza'!M15+'Salt Lake JC -21'!M15+'Forum Mall'!M15+'Lake Town'!M15+'Quest Mall'!M15+'Rosedale Plaza'!M15+'Mani Square Mall'!M15+'Forum Rangoli'!M15+CSC!M15+Jameslong!M15+Technopolis!M15+Santoshpur!M15+'Chinar Park'!M15+'Lake Road'!M15+Kalikapur!M15+'Event Sales'!M15+'Sector 1'!M15 -> 0 | O16: =sum(C16:N16) -> 5495838.2 | P16: =O16/$O$14 -> 0.041300895
A17: Telephone/Internet | B17: Operation | C17: ='Ideal Plaza'!B16+'Salt Lake JC -21'!B16+'Forum Mall'!B16+'Lake Town'!B16+'Quest Mall'!B16+'Rosedale Plaza'!B16+'Mani Square Mall'!B16+'Forum Rangoli'!B16+CSC!B16+Jameslong!B16+Technopolis!B16+Santoshpur!B16+'Chinar Park'!B16+'Lake Road'!B16+Kalikapur!B16+'Event Sales'!B16+'Sector 1'!B16 -> 13456.93 | D17: ='Ideal Plaza'!C16+'Salt Lake JC -21'!C16+'Forum Mall'!C16+'Lake Town'!C16+'Quest Mall'!C16+'Rosedale Plaza'!C16+'Mani Square Mall'!C16+'Forum Rangoli'!C16+CSC!C16+Jameslong!C16+Technopolis!C16+Santoshpur!C16+'Chinar Park'!C16+'Lake Road'!C16+Kalikapur!C16+'Event Sales'!C16+'Sector 1'!C16 -> 13956.93 | E17: ='Ideal Plaza'!D16+'Salt Lake JC -21'!D16+'Forum Mall'!D16+'Lake Town'!D16+'Quest Mall'!D16+'Rosedale Plaza'!D16+'Mani Square Mall'!D16+'Forum Rangoli'!D16+CSC!D16+Jameslong!D16+Technopolis!D16+Santoshpur!D16+'Chinar Park'!D16+'Lake Road'!D16+Kalikapur!D16+'Event Sales'!D16+'Sector 1'!D16 -> 13956.93 | F17: ='Ideal Plaza'!E16+'Salt Lake JC -21'!E16+'Forum Mall'!E16+'Lake Town'!E16+'Quest Mall'!E16+'Rosedale Plaza'!E16+'Mani Square Mall'!E16+'Forum Rangoli'!E16+CSC!E16+Jameslong!E16+Technopolis!E16+Santoshpur!E16+'Chinar Park'!E16+'Lake Road'!E16+Kalikapur!E16+'Event Sales'!E16+'Sector 1'!E16 -> 14315.263 | G17: ='Ideal Plaza'!F16+'Salt Lake JC -21'!F16+'Forum Mall'!F16+'Lake Town'!F16+'Quest Mall'!F16+'Rosedale Plaza'!F16+'Mani Square Mall'!F16+'Forum Rangoli'!F16+CSC!F16+Jameslong!F16+Technopolis!F16+Santoshpur!F16+'Chinar Park'!F16+'Lake Road'!F16+Kalikapur!F16+'Event Sales'!F16+'Sector 1'!F16 -> 12052.443 | H17: ='Ideal Plaza'!G16+'Salt Lake JC -21'!G16+'Forum Mall'!G16+'Lake Town'!G16+'Quest Mall'!G16+'Rosedale Plaza'!G16+'Mani Square Mall'!G16+'Forum Rangoli'!G16+CSC!G16+Jameslong!G16+Technopolis!G16+Santoshpur!G16+'Chinar Park'!G16+'Lake Road'!G16+Kalikapur!G16+'Event Sales'!G16+'Sector 1'!G16 -> 11849.443 | I17: ='Ideal Plaza'!H16+'Salt Lake JC -21'!H16+'Forum Mall'!H16+'Lake Town'!H16+'Quest Mall'!H16+'Rosedale Plaza'!H16+'Mani Square Mall'!H16+'Forum Rangoli'!H16+CSC!H16+Jameslong!H16+Technopolis!H16+Santoshpur!H16+'Chinar Park'!H16+'Lake Road'!H16+Kalikapur!H16+'Event Sales'!H16+'Sector 1'!H16 -> 948.33333 | J17: ='Ideal Plaza'!I16+'Salt Lake JC -21'!I16+'Forum Mall'!I16+'Lake Town'!I16+'Quest Mall'!I16+'Rosedale Plaza'!I16+'Mani Square Mall'!I16+'Forum Rangoli'!I16+CSC!I16+Jameslong!I16+Technopolis!I16+Santoshpur!I16+'Chinar Park'!H16+'Lake Road'!I16+Kalikapur!I16+'Event Sales'!I16+'Sector 1'!I16 -> 948.33333 | K17: ='Ideal Plaza'!J16+'Salt Lake JC -21'!J16+'Forum Mall'!J16+'Lake Town'!J16+'Quest Mall'!J16+'Rosedale Plaza'!J16+'Mani Square Mall'!J16+'Forum Rangoli'!J16+CSC!J16+Jameslong!J16+Technopolis!J16+Santoshpur!J16+'Chinar Park'!J16+'Lake Road'!J16+Kalikapur!J16+'Event Sales'!J16+'Sector 1'!J16 -> 948.33333 | L17: ='Ideal Plaza'!K16+'Salt Lake JC -21'!K16+'Forum Mall'!K16+'Lake Town'!K16+'Quest Mall'!K16+'Rosedale Plaza'!K16+'Mani Square Mall'!K16+'Forum Rangoli'!K16+CSC!K16+Jameslong!K16+Technopolis!K16+Santoshpur!K16+'Chinar Park'!K16+'Lake Road'!K16+Kalikapur!K16+'Event Sales'!K16+'Sector 1'!K16 -> 948.33333 | M17: ='Ideal Plaza'!L16+'Salt Lake JC -21'!L16+'Forum Mall'!L16+'Lake Town'!L16+'Quest Mall'!L16+'Rosedale Plaza'!L16+'Mani Square Mall'!L16+'Forum Rangoli'!L16+CSC!L16+Jameslong!L16+Technopolis!L16+Santoshpur!L16+'Chinar Park'!L16+'Lake Road'!L16+Kalikapur!L16+'Event Sales'!L16+'Sector 1'!L16 -> 948.33333 | N17: ='Ideal Plaza'!M16+'Salt Lake JC -21'!M16+'Forum Mall'!M16+'Lake Town'!M16+'Quest Mall'!M16+'Rosedale Plaza'!M16+'Mani Square Mall'!M16+'Forum Rangoli'!M16+CSC!M16+Jameslong!M16+Technopolis!M16+Santoshpur!M16+'Chinar Park'!M16+'Lake Road'!M16+Kalikapur!M16+'Event Sales'!M16+'Sector 1'!M16 -> 948.33333 | O17: =sum(C17:N17) -> 85277.94 | P17: =O17/$O$14 -> 0.00064085861
A18: Gas | B18: Operation | C18: ='Ideal Plaza'!B17+'Salt Lake JC -21'!B17+'Forum Mall'!B17+'Lake Town'!B17+'Quest Mall'!B17+'Rosedale Plaza'!B17+'Mani Square Mall'!B17+'Forum Rangoli'!B17+CSC!B17+Jameslong!B17+Technopolis!B17+Santoshpur!B17+'Chinar Park'!B17+'Lake Road'!B17+Kalikapur!B17+'Event Sales'!B17+'Sector 1'!B17 -> 238567 | D18: ='Ideal Plaza'!C17+'Salt Lake JC -21'!C17+'Forum Mall'!C17+'Lake Town'!C17+'Quest Mall'!C17+'Rosedale Plaza'!C17+'Mani Square Mall'!C17+'Forum Rangoli'!C17+CSC!C17+Jameslong!C17+Technopolis!C17+Santoshpur!C17+'Chinar Park'!C17+'Lake Road'!C17+Kalikapur!C17+'Event Sales'!C17+'Sector 1'!C17 -> 654017.84 | E18: ='Ideal Plaza'!D17+'Salt Lake JC -21'!D17+'Forum Mall'!D17+'Lake Town'!D17+'Quest Mall'!D17+'Rosedale Plaza'!D17+'Mani Square Mall'!D17+'Forum Rangoli'!D17+CSC!D17+Jameslong!D17+Technopolis!D17+Santoshpur!D17+'Chinar Park'!D17+'Lake Road'!D17+Kalikapur!D17+'Event Sales'!D17+'Sector 1'!D17 -> 643074.78 | F18: ='Ideal Plaza'!E17+'Salt Lake JC -21'!E17+'Forum Mall'!E17+'Lake Town'!E17+'Quest Mall'!E17+'Rosedale Plaza'!E17+'Mani Square Mall'!E17+'Forum Rangoli'!E17+CSC!E17+Jameslong!E17+Technopolis!E17+Santoshpur!E17+'Chinar Park'!E17+'Lake Road'!E17+Kalikapur!E17+'Event Sales'!E17+'Sector 1'!E17 -> 676849 | G18: ='Ideal Plaza'!F17+'Salt Lake JC -21'!F17+'Forum Mall'!F17+'Lake Town'!F17+'Quest Mall'!F17+'Rosedale Plaza'!F17+'Mani Square Mall'!F17+'Forum Rangoli'!F17+CSC!F17+Jameslong!F17+Technopolis!F17+Santoshpur!F17+'Chinar Park'!F17+'Lake Road'!F17+Kalikapur!F17+'Event Sales'!F17+'Sector 1'!F17 -> 603302.5 | H18: ='Ideal Plaza'!G17+'Salt Lake JC -21'!G17+'Forum Mall'!G17+'Lake Town'!G17+'Quest Mall'!G17+'Rosedale Plaza'!G17+'Mani Square Mall'!G17+'Forum Rangoli'!G17+CSC!G17+Jameslong!G17+Technopolis!G17+Santoshpur!G17+'Chinar Park'!G17+'Lake Road'!G17+Kalikapur!G17+'Event Sales'!G17+'Sector 1'!G17 -> 588948 | I18: ='Ideal Plaza'!H17+'Salt Lake JC -21'!H17+'Forum Mall'!H17+'Lake Town'!H17+'Quest Mall'!H17+'Rosedale Plaza'!H17+'Mani Square Mall'!H17+'Forum Rangoli'!H17+CSC!H17+Jameslong!H17+Technopolis!H17+Santoshpur!H17+'Chinar Park'!H17+'Lake Road'!H17+Kalikapur!H17+'Event Sales'!H17+'Sector 1'!H17 -> 0 | J18: ='Ideal Plaza'!I17+'Salt Lake JC -21'!I17+'Forum Mall'!I17+'Lake Town'!I17+'Quest Mall'!I17+'Rosedale Plaza'!I17+'Mani Square Mall'!I17+'Forum Rangoli'!I17+CSC!I17+Jameslong!I17+Technopolis!I17+Santoshpur!I17+'Chinar Park'!I17+'Lake Road'!I17+Kalikapur!I17+'Event Sales'!I17+'Sector 1'!I17 -> 0 | ... N18: ='Ideal Plaza'!M17+'Salt Lake JC -21'!M17+'Forum Mall'!M17+'Lake Town'!M17+'Quest Mall'!M17+'Rosedale Plaza'!M17+'Mani Square Mall'!M17+'Forum Rangoli'!M17+CSC!M17+Jameslong!M17+Technopolis!M17+Santoshpur!M17+'Chinar Park'!M17+'Lake Road'!M17+Kalikapur!M17+'Event Sales'!M17+'Sector 1'!M17 -> 0 | O18: =sum(C18:N18) -> 3404759.1 | P18: =O18/$O$14 -> 0.025586561
A19: Rent & Revenue Share | B19: Accounts | C19: ='Ideal Plaza'!B18+'Salt Lake JC -21'!B18+'Forum Mall'!B18+'Lake Town'!B18+'Quest Mall'!B18+'Rosedale Plaza'!B18+'Mani Square Mall'!B18+'Forum Rangoli'!B18+CSC!B18+Jameslong!B18+Technopolis!B18+Santoshpur!B18+'Chinar Park'!B18+'Lake Road'!B18+Kalikapur!B18+'Event Sales'!B18+'Sector 1'!B18 -> 2187486.8 | D19: ='Ideal Plaza'!C18+'Salt Lake JC -21'!C18+'Forum Mall'!C18+'Lake Town'!C18+'Quest Mall'!C18+'Rosedale Plaza'!C18+'Mani Square Mall'!C18+'Forum Rangoli'!C18+CSC!C18+Jameslong!C18+Technopolis!C18+Santoshpur!C18+'Chinar Park'!C18+'Lake Road'!C18+Kalikapur!C18+'Event Sales'!C18+'Sector 1'!C18 -> 2326525.1 | E19: ='Ideal Plaza'!D18+'Salt Lake JC -21'!D18+'Forum Mall'!D18+'Lake Town'!D18+'Quest Mall'!D18+'Rosedale Plaza'!D18+'Mani Square Mall'!D18+'Forum Rangoli'!D18+CSC!D18+Jameslong!D18+Technopolis!D18+Santoshpur!D18+'Chinar Park'!D18+'Lake Road'!D18+Kalikapur!D18+'Event Sales'!D18+'Sector 1'!D18 -> 2320904 | F19: ='Ideal Plaza'!E18+'Salt Lake JC -21'!E18+'Forum Mall'!E18+'Lake Town'!E18+'Quest Mall'!E18+'Rosedale Plaza'!E18+'Mani Square Mall'!E18+'Forum Rangoli'!E18+CSC!E18+Jameslong!E18+Technopolis!E18+Santoshpur!E18+'Chinar Park'!E18+'Lake Road'!E18+Kalikapur!E18+'Event Sales'!E18+'Sector 1'!E18 -> 2364561 | G19: ='Ideal Plaza'!F18+'Salt Lake JC -21'!F18+'Forum Mall'!F18+'Lake Town'!F18+'Quest Mall'!F18+'Rosedale Plaza'!F18+'Mani Square Mall'!F18+'Forum Rangoli'!F18+CSC!F18+Jameslong!F18+Technopolis!F18+Santoshpur!F18+'Chinar Park'!F18+'Lake Road'!F18+Kalikapur!F18+'Event Sales'!F18+'Sector 1'!F18 -> 2473572 | H19: ='Ideal Plaza'!G18+'Salt Lake JC -21'!G18+'Forum Mall'!G18+'Lake Town'!G18+'Quest Mall'!G18+'Rosedale Plaza'!G18+'Mani Square Mall'!G18+'Forum Rangoli'!G18+CSC!G18+Jameslong!G18+Technopolis!G18+Santoshpur!G18+'Chinar Park'!G18+'Lake Road'!G18+Kalikapur!G18+'Event Sales'!G18+'Sector 1'!G18 -> 2367593 | I19: ='Ideal Plaza'!H18+'Salt Lake JC -21'!H18+'Forum Mall'!H18+'Lake Town'!H18+'Quest Mall'!H18+'Rosedale Plaza'!H18+'Mani Square Mall'!H18+'Forum Rangoli'!H18+CSC!H18+Jameslong!H18+Technopolis!H18+Santoshpur!H18+'Chinar Park'!H18+'Lake Road'!H18+Kalikapur!H18+'Event Sales'!H18+'Sector 1'!H18 -> 0 | J19: ='Ideal Plaza'!I18+'Salt Lake JC -21'!I18+'Forum Mall'!I18+'Lake Town'!I18+'Quest Mall'!I18+'Rosedale Plaza'!I18+'Mani Square Mall'!I18+'Forum Rangoli'!I18+CSC!I18+Jameslong!I18+Technopolis!I18+Santoshpur!I18+'Chinar Park'!I18+'Lake Road'!I18+Kalikapur!I18+'Event Sales'!I18+'Sector 1'!I18 -> 0 | ... N19: ='Ideal Plaza'!M18+'Salt Lake JC -21'!M18+'Forum Mall'!M18+'Lake Town'!M18+'Quest Mall'!M18+'Rosedale Plaza'!M18+'Mani Square Mall'!M18+'Forum Rangoli'!M18+CSC!M18+Jameslong!M18+Technopolis!M18+Santoshpur!M18+'Chinar Park'!M18+'Lake Road'!M18+Kalikapur!M18+'Event Sales'!M18+'Sector 1'!M18 -> 0 | O19: =sum(C19:N19) -> 14040642 | P19: =O19/$O$14 -> 0.10551458
A20: Software | B20: Operation | C20: ='Ideal Plaza'!B19+'Salt Lake JC -21'!B19+'Forum Mall'!B19+'Lake Town'!B19+'Quest Mall'!B19+'Rosedale Plaza'!B19+'Mani Square Mall'!B19+'Forum Rangoli'!B19+CSC!B19+Jameslong!B19+Technopolis!B19+Santoshpur!B19+'Chinar Park'!B19+'Lake Road'!B19+Kalikapur!B19+'Event Sales'!B19+'Sector 1'!B19 -> 72993.57 | D20: ='Ideal Plaza'!C19+'Salt Lake JC -21'!C19+'Forum Mall'!C19+'Lake Town'!C19+'Quest Mall'!C19+'Rosedale Plaza'!C19+'Mani Square Mall'!C19+'Forum Rangoli'!C19+CSC!C19+Jameslong!C19+Technopolis!C19+Santoshpur!C19+'Chinar Park'!C19+'Lake Road'!C19+Kalikapur!C19+'Event Sales'!C19+'Sector 1'!C19 -> 72993.57 | E20: ='Ideal Plaza'!D19+'Salt Lake JC -21'!D19+'Forum Mall'!D19+'Lake Town'!D19+'Quest Mall'!D19+'Rosedale Plaza'!D19+'Mani Square Mall'!D19+'Forum Rangoli'!D19+CSC!D19+Jameslong!D19+Technopolis!D19+Santoshpur!D19+'Chinar Park'!D19+'Lake Road'!D19+Kalikapur!D19+'Event Sales'!D19+'Sector 1'!D19 -> 72993.57 | F20: ='Ideal Plaza'!E19+'Salt Lake JC -21'!E19+'Forum Mall'!E19+'Lake Town'!E19+'Quest Mall'!E19+'Rosedale Plaza'!E19+'Mani Square Mall'!E19+'Forum Rangoli'!E19+CSC!E19+Jameslong!E19+Technopolis!E19+Santoshpur!E19+'Chinar Park'!E19+'Lake Road'!E19+Kalikapur!E19+'Event Sales'!E19+'Sector 1'!E19 -> 72993.57 | G20: ='Ideal Plaza'!F19+'Salt Lake JC -21'!F19+'Forum Mall'!F19+'Lake Town'!F19+'Quest Mall'!F19+'Rosedale Plaza'!F19+'Mani Square Mall'!F19+'Forum Rangoli'!F19+CSC!F19+Jameslong!F19+Technopolis!F19+Santoshpur!F19+'Chinar Park'!F19+'Lake Road'!F19+Kalikapur!F19+'Event Sales'!F19+'Sector 1'!F19 -> 73035.07 | H20: ='Ideal Plaza'!G19+'Salt Lake JC -21'!G19+'Forum Mall'!G19+'Lake Town'!G19+'Quest Mall'!G19+'Rosedale Plaza'!G19+'Mani Square Mall'!G19+'Forum Rangoli'!G19+CSC!G19+Jameslong!G19+Technopolis!G19+Santoshpur!G19+'Chinar Park'!G19+'Lake Road'!G19+Kalikapur!G19+'Event Sales'!G19+'Sector 1'!G19 -> 73035.07 | I20: ='Ideal Plaza'!H19+'Salt Lake JC -21'!H19+'Forum Mall'!H19+'Lake Town'!H19+'Quest Mall'!H19+'Rosedale Plaza'!H19+'Mani Square Mall'!H19+'Forum Rangoli'!H19+CSC!H19+Jameslong!H19+Technopolis!H19+Santoshpur!H19+'Chinar Park'!H19+'Lake Road'!H19+Kalikapur!H19+'Event Sales'!H19+'Sector 1'!H19 -> 11534.5 | J20: ='Ideal Plaza'!I19+'Salt Lake JC -21'!I19+'Forum Mall'!I19+'Lake Town'!I19+'Quest Mall'!I19+'Rosedale Plaza'!I19+'Mani Square Mall'!I19+'Forum Rangoli'!I19+CSC!I19+Jameslong!I19+Technopolis!I19+Santoshpur!I19+'Chinar Park'!I19+'Lake Road'!I19+Kalikapur!I19+'Event Sales'!I19+'Sector 1'!I19 -> 11534.5 | ... N20: ='Ideal Plaza'!M19+'Salt Lake JC -21'!M19+'Forum Mall'!M19+'Lake Town'!M19+'Quest Mall'!M19+'Rosedale Plaza'!M19+'Mani Square Mall'!M19+'Forum Rangoli'!M19+CSC!M19+Jameslong!M19+Technopolis!M19+Santoshpur!M19+'Chinar Park'!M19+'Lake Road'!M19+Kalikapur!M19+'Event Sales'!M19+'Sector 1'!M19 -> 11534.5 | O20: =sum(C20:N20) -> 507251.42 | P20: =O20/$O$14 -> 0.003811964
A21: Staff Salary | B21: HR | C21: ='Ideal Plaza'!B20+'Salt Lake JC -21'!B20+'Forum Mall'!B20+'Lake Town'!B20+'Quest Mall'!B20+'Rosedale Plaza'!B20+'Mani Square Mall'!B20+'Forum Rangoli'!B20+CSC!B20+Jameslong!B20+Technopolis!B20+Santoshpur!B20+'Chinar Park'!B20+'Lake Road'!B20+Kalikapur!B20+'Event Sales'!B20+'Sector 1'!B20 -> 3298909 | D21: ='Ideal Plaza'!C20+'Salt Lake JC -21'!C20+'Forum Mall'!C20+'Lake Town'!C20+'Quest Mall'!C20+'Rosedale Plaza'!C20+'Mani Square Mall'!C20+'Forum Rangoli'!C20+CSC!C20+Jameslong!C20+Technopolis!C20+Santoshpur!C20+'Chinar Park'!C20+'Lake Road'!C20+Kalikapur!C20+'Event Sales'!C20+'Sector 1'!C20 -> 3578266 | E21: ='Ideal Plaza'!D20+'Salt Lake JC -21'!D20+'Forum Mall'!D20+'Lake Town'!D20+'Quest Mall'!D20+'Rosedale Plaza'!D20+'Mani Square Mall'!D20+'Forum Rangoli'!D20+CSC!D20+Jameslong!D20+Technopolis!D20+Santoshpur!D20+'Chinar Park'!D20+'Lake Road'!D20+Kalikapur!D20+'Event Sales'!D20+'Sector 1'!D20 -> 3621953.4 | F21: ='Ideal Plaza'!E20+'Salt Lake JC -21'!E20+'Forum Mall'!E20+'Lake Town'!E20+'Quest Mall'!E20+'Rosedale Plaza'!E20+'Mani Square Mall'!E20+'Forum Rangoli'!E20+CSC!E20+Jameslong!E20+Technopolis!E20+Santoshpur!E20+'Chinar Park'!E20+'Lake Road'!E20+Kalikapur!E20+'Event Sales'!E20+'Sector 1'!E20 -> 3670111.9 | G21: ='Ideal Plaza'!F20+'Salt Lake JC -21'!F20+'Forum Mall'!F20+'Lake Town'!F20+'Quest Mall'!F20+'Rosedale Plaza'!F20+'Mani Square Mall'!F20+'Forum Rangoli'!F20+CSC!F20+Jameslong!F20+Technopolis!F20+Santoshpur!F20+'Chinar Park'!F20+'Lake Road'!F20+Kalikapur!F20+'Event Sales'!F20+'Sector 1'!F20 -> 3488719 | H21: ='Ideal Plaza'!G20+'Salt Lake JC -21'!G20+'Forum Mall'!G20+'Lake Town'!G20+'Quest Mall'!G20+'Rosedale Plaza'!G20+'Mani Square Mall'!G20+'Forum Rangoli'!G20+CSC!G20+Jameslong!G20+Technopolis!G20+Santoshpur!G20+'Chinar Park'!G20+'Lake Road'!G20+Kalikapur!G20+'Event Sales'!G20+'Sector 1'!G20 -> 3541701 | I21: ='Ideal Plaza'!H20+'Salt Lake JC -21'!H20+'Forum Mall'!H20+'Lake Town'!H20+'Quest Mall'!H20+'Rosedale Plaza'!H20+'Mani Square Mall'!H20+'Forum Rangoli'!H20+CSC!H20+Jameslong!H20+Technopolis!H20+Santoshpur!H20+'Chinar Park'!H20+'Lake Road'!H20+Kalikapur!H20+'Event Sales'!H20+'Sector 1'!H20 -> 0 | J21: ='Ideal Plaza'!I20+'Salt Lake JC -21'!I20+'Forum Mall'!I20+'Lake Town'!I20+'Quest Mall'!I20+'Rosedale Plaza'!I20+'Mani Square Mall'!I20+'Forum Rangoli'!I20+CSC!I20+Jameslong!I20+Technopolis!I20+Santoshpur!I20+'Chinar Park'!I20+'Lake Road'!I20+Kalikapur!I20+'Event Sales'!I20+'Sector 1'!I20 -> 0 | ... N21: ='Ideal Plaza'!M20+'Salt Lake JC -21'!M20+'Forum Mall'!M20+'Lake Town'!M20+'Quest Mall'!M20+'Rosedale Plaza'!M20+'Mani Square Mall'!M20+'Forum Rangoli'!M20+CSC!M20+Jameslong!M20+Technopolis!M20+Santoshpur!M20+'Chinar Park'!M20+'Lake Road'!M20+Kalikapur!M20+'Event Sales'!M20+'Sector 1'!M20 -> 0 | O21: =sum(C21:N21) -> 21199660 | P21: =O21/$O$14 -> 0.15931418
A22: AMC | B22: Operation | C22: ='Ideal Plaza'!B21+'Salt Lake JC -21'!B21+'Forum Mall'!B21+'Lake Town'!B21+'Quest Mall'!B21+'Rosedale Plaza'!B21+'Mani Square Mall'!B21+'Forum Rangoli'!B21+CSC!B21+Jameslong!B21+Technopolis!B21+Santoshpur!B21+'Chinar Park'!B21+'Lake Road'!B21+Kalikapur!B21+'Event Sales'!B21+'Sector 1'!B21 -> 125462 | D22: ='Ideal Plaza'!C21+'Salt Lake JC -21'!C21+'Forum Mall'!C21+'Lake Town'!C21+'Quest Mall'!C21+'Rosedale Plaza'!C21+'Mani Square Mall'!C21+'Forum Rangoli'!C21+CSC!C21+Jameslong!C21+Technopolis!C21+Santoshpur!C21+'Chinar Park'!C21+'Lake Road'!C21+Kalikapur!C21+'Event Sales'!C21+'Sector 1'!C21 -> 136575 | E22: ='Ideal Plaza'!D21+'Salt Lake JC -21'!D21+'Forum Mall'!D21+'Lake Town'!D21+'Quest Mall'!D21+'Rosedale Plaza'!D21+'Mani Square Mall'!D21+'Forum Rangoli'!D21+CSC!D21+Jameslong!D21+Technopolis!D21+Santoshpur!D21+'Chinar Park'!D21+'Lake Road'!D21+Kalikapur!D21+'Event Sales'!D21+'Sector 1'!D21 -> 128253 | F22: ='Ideal Plaza'!E21+'Salt Lake JC -21'!E21+'Forum Mall'!E21+'Lake Town'!E21+'Quest Mall'!E21+'Rosedale Plaza'!E21+'Mani Square Mall'!E21+'Forum Rangoli'!E21+CSC!E21+Jameslong!E21+Technopolis!E21+Santoshpur!E21+'Chinar Park'!E21+'Lake Road'!E21+Kalikapur!E21+'Event Sales'!E21+'Sector 1'!E21 -> 124135 | G22: ='Ideal Plaza'!F21+'Salt Lake JC -21'!F21+'Forum Mall'!F21+'Lake Town'!F21+'Quest Mall'!F21+'Rosedale Plaza'!F21+'Mani Square Mall'!F21+'Forum Rangoli'!F21+CSC!F21+Jameslong!F21+Technopolis!F21+Santoshpur!F21+'Chinar Park'!F21+'Lake Road'!F21+Kalikapur!F21+'Event Sales'!F21+'Sector 1'!F21 -> 130632 | H22: ='Ideal Plaza'!G21+'Salt Lake JC -21'!G21+'Forum Mall'!G21+'Lake Town'!G21+'Quest Mall'!G21+'Rosedale Plaza'!G21+'Mani Square Mall'!G21+'Forum Rangoli'!G21+CSC!G21+Jameslong!G21+Technopolis!G21+Santoshpur!G21+'Chinar Park'!G21+'Lake Road'!G21+Kalikapur!G21+'Event Sales'!G21+'Sector 1'!G21 -> 130632 | I22: ='Ideal Plaza'!H21+'Salt Lake JC -21'!H21+'Forum Mall'!H21+'Lake Town'!H21+'Quest Mall'!H21+'Rosedale Plaza'!H21+'Mani Square Mall'!H21+'Forum Rangoli'!H21+CSC!H21+Jameslong!H21+Technopolis!H21+Santoshpur!H21+'Chinar Park'!H21+'Lake Road'!H21+Kalikapur!H21+'Event Sales'!H21+'Sector 1'!H21 -> 0 | J22: ='Ideal Plaza'!I21+'Salt Lake JC -21'!I21+'Forum Mall'!I21+'Lake Town'!I21+'Quest Mall'!I21+'Rosedale Plaza'!I21+'Mani Square Mall'!I21+'Forum Rangoli'!I21+CSC!I21+Jameslong!I21+Technopolis!I21+Santoshpur!I21+'Chinar Park'!I21+'Lake Road'!I21+Kalikapur!I21+'Event Sales'!I21+'Sector 1'!I21 -> 0 | ... N22: ='Ideal Plaza'!M21+'Salt Lake JC -21'!M21+'Forum Mall'!M21+'Lake Town'!M21+'Quest Mall'!M21+'Rosedale Plaza'!M21+'Mani Square Mall'!M21+'Forum Rangoli'!M21+CSC!M21+Jameslong!M21+Technopolis!M21+Santoshpur!M21+'Chinar Park'!M21+'Lake Road'!M21+Kalikapur!M21+'Event Sales'!M21+'Sector 1'!M21 -> 0 | O22: =sum(C22:N22) -> 775689 | P22: =O22/$O$14 -> 0.0058292564
A23: Subscription | B23: Operation | C23: ='Ideal Plaza'!B22+'Salt Lake JC -21'!B22+'Forum Mall'!B22+'Lake Town'!B22+'Quest Mall'!B22+'Rosedale Plaza'!B22+'Mani Square Mall'!B22+'Forum Rangoli'!B22+CSC!B22+Jameslong!B22+Technopolis!B22+Santoshpur!B22+'Chinar Park'!B22+'Lake Road'!B22+Kalikapur!B22+'Event Sales'!B22+'Sector 1'!B22 -> 50296.36 | D23: ='Ideal Plaza'!C22+'Salt Lake JC -21'!C22+'Forum Mall'!C22+'Lake Town'!C22+'Quest Mall'!C22+'Rosedale Plaza'!C22+'Mani Square Mall'!C22+'Forum Rangoli'!C22+CSC!C22+Jameslong!C22+Technopolis!C22+Santoshpur!C22+'Chinar Park'!C22+'Lake Road'!C22+Kalikapur!C22+'Event Sales'!C22+'Sector 1'!C22 -> 50296.36 | E23: ='Ideal Plaza'!D22+'Salt Lake JC -21'!D22+'Forum Mall'!D22+'Lake Town'!D22+'Quest Mall'!D22+'Rosedale Plaza'!D22+'Mani Square Mall'!D22+'Forum Rangoli'!D22+CSC!D22+Jameslong!D22+Technopolis!D22+Santoshpur!D22+'Chinar Park'!D22+'Lake Road'!D22+Kalikapur!D22+'Event Sales'!D22+'Sector 1'!D22 -> 50296.36 | F23: ='Ideal Plaza'!E22+'Salt Lake JC -21'!E22+'Forum Mall'!E22+'Lake Town'!E22+'Quest Mall'!E22+'Rosedale Plaza'!E22+'Mani Square Mall'!E22+'Forum Rangoli'!E22+CSC!E22+Jameslong!E22+Technopolis!E22+Santoshpur!E22+'Chinar Park'!E22+'Lake Road'!E22+Kalikapur!E22+'Event Sales'!E22+'Sector 1'!E22 -> 50296.36 | G23: ='Ideal Plaza'!F22+'Salt Lake JC -21'!F22+'Forum Mall'!F22+'Lake Town'!F22+'Quest Mall'!F22+'Rosedale Plaza'!F22+'Mani Square Mall'!F22+'Forum Rangoli'!F22+CSC!F22+Jameslong!F22+Technopolis!F22+Santoshpur!F22+'Chinar Park'!F22+'Lake Road'!F22+Kalikapur!F22+'Event Sales'!F22+'Sector 1'!F22 -> 50296.36 | H23: ='Ideal Plaza'!G22+'Salt Lake JC -21'!G22+'Forum Mall'!G22+'Lake Town'!G22+'Quest Mall'!G22+'Rosedale Plaza'!G22+'Mani Square Mall'!G22+'Forum Rangoli'!G22+CSC!G22+Jameslong!G22+Technopolis!G22+Santoshpur!G22+'Chinar Park'!G22+'Lake Road'!G22+Kalikapur!G22+'Event Sales'!G22+'Sector 1'!G22 -> 50296.36 | I23: ='Ideal Plaza'!H22+'Salt Lake JC -21'!H22+'Forum Mall'!H22+'Lake Town'!H22+'Quest Mall'!H22+'Rosedale Plaza'!H22+'Mani Square Mall'!H22+'Forum Rangoli'!H22+CSC!H22+Jameslong!H22+Technopolis!H22+Santoshpur!H22+'Chinar Park'!H22+'Lake Road'!H22+Kalikapur!H22+'Event Sales'!H22+'Sector 1'!H22 -> 18919.16 | J23: ='Ideal Plaza'!I22+'Salt Lake JC -21'!I22+'Forum Mall'!I22+'Lake Town'!I22+'Quest Mall'!I22+'Rosedale Plaza'!I22+'Mani Square Mall'!I22+'Forum Rangoli'!I22+CSC!I22+Jameslong!I22+Technopolis!I22+Santoshpur!I22+'Chinar Park'!I22+'Lake Road'!I22+Kalikapur!I22+'Event Sales'!I22+'Sector 1'!I22 -> 17490.44 | ... N23: ='Ideal Plaza'!M22+'Salt Lake JC -21'!M22+'Forum Mall'!M22+'Lake Town'!M22+'Quest Mall'!M22+'Rosedale Plaza'!M22+'Mani Square Mall'!M22+'Forum Rangoli'!M22+CSC!M22+Jameslong!M22+Technopolis!M22+Santoshpur!M22+'Chinar Park'!M22+'Lake Road'!M22+Kalikapur!M22+'Event Sales'!M22+'Sector 1'!M22 -> 17490.44 | O23: =sum(C23:N23) -> 408149.52 | P23: =O23/$O$14 -> 0.0030672192
A24: Insurance | B24: Development | C24: ='Ideal Plaza'!B23+'Salt Lake JC -21'!B23+'Forum Mall'!B23+'Lake Town'!B23+'Quest Mall'!B23+'Rosedale Plaza'!B23+'Mani Square Mall'!B23+'Forum Rangoli'!B23+CSC!B23+Jameslong!B23+Technopolis!B23+Santoshpur!B23+'Chinar Park'!B23+'Lake Road'!B23+Kalikapur!B23+'Event Sales'!B23+'Sector 1'!B23 -> 14966.188 | D24: ='Ideal Plaza'!C23+'Salt Lake JC -21'!C23+'Forum Mall'!C23+'Lake Town'!C23+'Quest Mall'!C23+'Rosedale Plaza'!C23+'Mani Square Mall'!C23+'Forum Rangoli'!C23+CSC!C23+Jameslong!C23+Technopolis!C23+Santoshpur!C23+'Chinar Park'!C23+'Lake Road'!C23+Kalikapur!C23+'Event Sales'!C23+'Sector 1'!C23 -> 25502.658 | E24: ='Ideal Plaza'!D23+'Salt Lake JC -21'!D23+'Forum Mall'!D23+'Lake Town'!D23+'Quest Mall'!D23+'Rosedale Plaza'!D23+'Mani Square Mall'!D23+'Forum Rangoli'!D23+CSC!D23+Jameslong!D23+Technopolis!D23+Santoshpur!D23+'Chinar Park'!D23+'Lake Road'!D23+Kalikapur!D23+'Event Sales'!D23+'Sector 1'!D23 -> 25502.658 | F24: ='Ideal Plaza'!E23+'Salt Lake JC -21'!E23+'Forum Mall'!E23+'Lake Town'!E23+'Quest Mall'!E23+'Rosedale Plaza'!E23+'Mani Square Mall'!E23+'Forum Rangoli'!E23+CSC!E23+Jameslong!E23+Technopolis!E23+Santoshpur!E23+'Chinar Park'!E23+'Lake Road'!E23+Kalikapur!E23+'Event Sales'!E23+'Sector 1'!E23 -> 25502.658 | G24: ='Ideal Plaza'!F23+'Salt Lake JC -21'!F23+'Forum Mall'!F23+'Lake Town'!F23+'Quest Mall'!F23+'Rosedale Plaza'!F23+'Mani Square Mall'!F23+'Forum Rangoli'!F23+CSC!F23+Jameslong!F23+Technopolis!F23+Santoshpur!F23+'Chinar Park'!F23+'Lake Road'!F23+Kalikapur!F23+'Event Sales'!F23+'Sector 1'!F23 -> 25502.658 | H24: ='Ideal Plaza'!G23+'Salt Lake JC -21'!G23+'Forum Mall'!G23+'Lake Town'!G23+'Quest Mall'!G23+'Rosedale Plaza'!G23+'Mani Square Mall'!G23+'Forum Rangoli'!G23+CSC!G23+Jameslong!G23+Technopolis!G23+Santoshpur!G23+'Chinar Park'!G23+'Lake Road'!G23+Kalikapur!G23+'Event Sales'!G23+'Sector 1'!G23 -> 25502.658 | I24: ='Ideal Plaza'!H23+'Salt Lake JC -21'!H23+'Forum Mall'!H23+'Lake Town'!H23+'Quest Mall'!H23+'Rosedale Plaza'!H23+'Mani Square Mall'!H23+'Forum Rangoli'!H23+CSC!H23+Jameslong!H23+Technopolis!H23+Santoshpur!H23+'Chinar Park'!H23+'Lake Road'!H23+Kalikapur!H23+'Event Sales'!H23+'Sector 1'!H23 -> 25502.658 | J24: ='Ideal Plaza'!I23+'Salt Lake JC -21'!I23+'Forum Mall'!I23+'Lake Town'!I23+'Quest Mall'!I23+'Rosedale Plaza'!I23+'Mani Square Mall'!I23+'Forum Rangoli'!I23+CSC!I23+Jameslong!I23+Technopolis!I23+Santoshpur!I23+'Chinar Park'!I23+'Lake Road'!I23+Kalikapur!I23+'Event Sales'!I23+'Sector 1'!I23 -> 25502.658 | ... N24: ='Ideal Plaza'!M23+'Salt Lake JC -21'!M23+'Forum Mall'!M23+'Lake Town'!M23+'Quest Mall'!M23+'Rosedale Plaza'!M23+'Mani Square Mall'!M23+'Forum Rangoli'!M23+CSC!M23+Jameslong!M23+Technopolis!M23+Santoshpur!M23+'Chinar Park'!M23+'Lake Road'!M23+Kalikapur!M23+'Event Sales'!M23+'Sector 1'!M23 -> 25502.658 | O24: =sum(C24:N24) -> 295495.43 | P24: =O24/$O$14 -> 0.0022206305
A25: Repairs & Maintenance | B25: Operation | C25: ='Ideal Plaza'!B24+'Salt Lake JC -21'!B24+'Forum Mall'!B24+'Lake Town'!B24+'Quest Mall'!B24+'Rosedale Plaza'!B24+'Mani Square Mall'!B24+'Forum Rangoli'!B24+CSC!B24+Jameslong!B24+Technopolis!B24+Santoshpur!B24+'Chinar Park'!B24+'Lake Road'!B24+Kalikapur!B24+'Event Sales'!B24+'Sector 1'!B24 -> 58719.22 | D25: ='Ideal Plaza'!C24+'Salt Lake JC -21'!C24+'Forum Mall'!C24+'Lake Town'!C24+'Quest Mall'!C24+'Rosedale Plaza'!C24+'Mani Square Mall'!C24+'Forum Rangoli'!C24+CSC!C24+Jameslong!C24+Technopolis!C24+Santoshpur!C24+'Chinar Park'!C24+'Lake Road'!C24+Kalikapur!C24+'Event Sales'!C24+'Sector 1'!C24 -> 53248 | E25: ='Ideal Plaza'!D24+'Salt Lake JC -21'!D24+'Forum Mall'!D24+'Lake Town'!D24+'Quest Mall'!D24+'Rosedale Plaza'!D24+'Mani Square Mall'!D24+'Forum Rangoli'!D24+CSC!D24+Jameslong!D24+Technopolis!D24+Santoshpur!D24+'Chinar Park'!D24+'Lake Road'!D24+Kalikapur!D24+'Event Sales'!D24+'Sector 1'!D24 -> 228298 | F25: ='Ideal Plaza'!E24+'Salt Lake JC -21'!E24+'Forum Mall'!E24+'Lake Town'!E24+'Quest Mall'!E24+'Rosedale Plaza'!E24+'Mani Square Mall'!E24+'Forum Rangoli'!E24+CSC!E24+Jameslong!E24+Technopolis!E24+Santoshpur!E24+'Chinar Park'!E24+'Lake Road'!E24+Kalikapur!E24+'Event Sales'!E24+'Sector 1'!E24 -> 140553 | G25: ='Ideal Plaza'!F24+'Salt Lake JC -21'!F24+'Forum Mall'!F24+'Lake Town'!F24+'Quest Mall'!F24+'Rosedale Plaza'!F24+'Mani Square Mall'!F24+'Forum Rangoli'!F24+CSC!F24+Jameslong!F24+Technopolis!F24+Santoshpur!F24+'Chinar Park'!F24+'Lake Road'!F24+Kalikapur!F24+'Event Sales'!F24+'Sector 1'!F24 -> 542734 | H25: ='Ideal Plaza'!G24+'Salt Lake JC -21'!G24+'Forum Mall'!G24+'Lake Town'!G24+'Quest Mall'!G24+'Rosedale Plaza'!G24+'Mani Square Mall'!G24+'Forum Rangoli'!G24+CSC!G24+Jameslong!G24+Technopolis!G24+Santoshpur!G24+'Chinar Park'!G24+'Lake Road'!G24+Kalikapur!G24+'Event Sales'!G24+'Sector 1'!G24 -> 89813 | I25: ='Ideal Plaza'!H24+'Salt Lake JC -21'!H24+'Forum Mall'!H24+'Lake Town'!H24+'Quest Mall'!H24+'Rosedale Plaza'!H24+'Mani Square Mall'!H24+'Forum Rangoli'!H24+CSC!H24+Jameslong!H24+Technopolis!H24+Santoshpur!H24+'Chinar Park'!H24+'Lake Road'!H24+Kalikapur!H24+'Event Sales'!H24+'Sector 1'!H24 -> 0 | J25: ='Ideal Plaza'!I24+'Salt Lake JC -21'!I24+'Forum Mall'!I24+'Lake Town'!I24+'Quest Mall'!I24+'Rosedale Plaza'!I24+'Mani Square Mall'!I24+'Forum Rangoli'!I24+CSC!I24+Jameslong!I24+Technopolis!I24+Santoshpur!I24+'Chinar Park'!I24+'Lake Road'!I24+Kalikapur!I24+'Event Sales'!I24+'Sector 1'!I24 -> 0 | ... N25: ='Ideal Plaza'!M24+'Salt Lake JC -21'!M24+'Forum Mall'!M24+'Lake Town'!M24+'Quest Mall'!M24+'Rosedale Plaza'!M24+'Mani Square Mall'!M24+'Forum Rangoli'!M24+CSC!M24+Jameslong!M24+Technopolis!M24+Santoshpur!M24+'Chinar Park'!M24+'Lake Road'!M24+Kalikapur!M24+'Event Sales'!M24+'Sector 1'!M24 -> 0 | O25: =sum(C25:N25) -> 1113365.2 | P25: =O25/$O$14 -> 0.0083668729
A26: Miscellaneous Expenses | B26: Accounts | C26: ='Ideal Plaza'!B25+'Salt Lake JC -21'!B25+'Forum Mall'!B25+'Lake Town'!B25+'Quest Mall'!B25+'Rosedale Plaza'!B25+'Mani Square Mall'!B25+'Forum Rangoli'!B25+CSC!B25+Jameslong!B25+Technopolis!B25+Santoshpur!B25+'Chinar Park'!B25+'Lake Road'!B25+Kalikapur!B25+'Event Sales'!B25+'Sector 1'!B25 -> 157014.64 | D26: ='Ideal Plaza'!C25+'Salt Lake JC -21'!C25+'Forum Mall'!C25+'Lake Town'!C25+'Quest Mall'!C25+'Rosedale Plaza'!C25+'Mani Square Mall'!C25+'Forum Rangoli'!C25+CSC!C25+Jameslong!C25+Technopolis!C25+Santoshpur!C25+'Chinar Park'!C25+'Lake Road'!C25+Kalikapur!C25+'Event Sales'!C25+'Sector 1'!C25 -> 416061.46 | E26: ='Ideal Plaza'!D25+'Salt Lake JC -21'!D25+'Forum Mall'!D25+'Lake Town'!D25+'Quest Mall'!D25+'Rosedale Plaza'!D25+'Mani Square Mall'!D25+'Forum Rangoli'!D25+CSC!D25+Jameslong!D25+Technopolis!D25+Santoshpur!D25+'Chinar Park'!D25+'Lake Road'!D25+Kalikapur!D25+'Event Sales'!D25+'Sector 1'!D25 -> 187253.33 | F26: ='Ideal Plaza'!E25+'Salt Lake JC -21'!E25+'Forum Mall'!E25+'Lake Town'!E25+'Quest Mall'!E25+'Rosedale Plaza'!E25+'Mani Square Mall'!E25+'Forum Rangoli'!E25+CSC!E25+Jameslong!E25+Technopolis!E25+Santoshpur!E25+'Chinar Park'!E25+'Lake Road'!E25+Kalikapur!E25+'Event Sales'!E25+'Sector 1'!E25 -> 443123.53 | G26: ='Ideal Plaza'!F25+'Salt Lake JC -21'!F25+'Forum Mall'!F25+'Lake Town'!F25+'Quest Mall'!F25+'Rosedale Plaza'!F25+'Mani Square Mall'!F25+'Forum Rangoli'!F25+CSC!F25+Jameslong!F25+Technopolis!F25+Santoshpur!F25+'Chinar Park'!F25+'Lake Road'!F25+Kalikapur!F25+'Event Sales'!F25+'Sector 1'!F25 -> 202752.69 | H26: ='Ideal Plaza'!G25+'Salt Lake JC -21'!G25+'Forum Mall'!G25+'Lake Town'!G25+'Quest Mall'!G25+'Rosedale Plaza'!G25+'Mani Square Mall'!G25+'Forum Rangoli'!G25+CSC!G25+Jameslong!G25+Technopolis!G25+Santoshpur!G25+'Chinar Park'!G25+'Lake Road'!G25+Kalikapur!G25+'Event Sales'!G25+'Sector 1'!G25 -> 372301.15 | I26: ='Ideal Plaza'!H25+'Salt Lake JC -21'!H25+'Forum Mall'!H25+'Lake Town'!H25+'Quest Mall'!H25+'Rosedale Plaza'!H25+'Mani Square Mall'!H25+'Forum Rangoli'!H25+CSC!H25+Jameslong!H25+Technopolis!H25+Santoshpur!H25+'Chinar Park'!H25+'Lake Road'!H25+Kalikapur!H25+'Event Sales'!H25+'Sector 1'!H25 -> 31375.083 | J26: ='Ideal Plaza'!I25+'Salt Lake JC -21'!I25+'Forum Mall'!I25+'Lake Town'!I25+'Quest Mall'!I25+'Rosedale Plaza'!I25+'Mani Square Mall'!I25+'Forum Rangoli'!I25+CSC!I25+Jameslong!I25+Technopolis!I25+Santoshpur!I25+'Chinar Park'!I25+'Lake Road'!I25+Kalikapur!I25+'Event Sales'!I25+'Sector 1'!I25 -> 31375.083 | ... N26: ='Ideal Plaza'!M25+'Salt Lake JC -21'!M25+'Forum Mall'!M25+'Lake Town'!M25+'Quest Mall'!M25+'Rosedale Plaza'!M25+'Mani Square Mall'!M25+'Forum Rangoli'!M25+CSC!M25+Jameslong!M25+Technopolis!M25+Santoshpur!M25+'Chinar Park'!M25+'Lake Road'!M25+Kalikapur!M25+'Event Sales'!M25+'Sector 1'!M25 -> 31375.083 | O26: =sum(C26:N26) -> 1966757.3 | P26: =O26/$O$14 -> 0.014780063
