Workbook

Sheet Summary
A2: Dosa Coffee - NCR | B2: Department | C2: 45748 | D2: 45778 | E2: 45809 | F2: 45839 | G2: 45870 | H2: 45901 | I2: 45931 | J2: 45962 | K2: 45992 | L2: 46023 | M2: 46054 | N2: 46082 | O2: FY 2025-26
A3: Food Cost Calculation
A4: Opening Stock | B4: Procurement | C4: ='Noida Sec - 18'!B3+'Noida Sec -143'!B3+DLF!B3+'Faridabad Sec15'!B3+'Gurgaon Sec-15'!B3+'Gurgaon Sec - 10'!B3+'Paschim Vihar'!B3+Kalkaji!B3+CP!B3+Rohini!B3+'Model Town'!B3+'Pacific Mall'!B3 -> 993716 | D4: ='Noida Sec - 18'!C3+'Noida Sec -143'!C3+DLF!C3+'Faridabad Sec15'!C3+'Gurgaon Sec-15'!C3+'Gurgaon Sec - 10'!C3+'Paschim Vihar'!C3+Kalkaji!C3+CP!C3+Rohini!C3+'Model Town'!C3+'Pacific Mall'!C3 -> 985593.38 | E4: ='Noida Sec - 18'!D3+'Noida Sec -143'!D3+DLF!D3+'Faridabad Sec15'!D3+'Gurgaon Sec-15'!D3+'Gurgaon Sec - 10'!D3+'Paschim Vihar'!D3+Kalkaji!D3+CP!D3+Rohini!D3+'Model Town'!D3+'Pacific Mall'!D3 -> 1011915 | F4: ='Noida Sec - 18'!E3+'Noida Sec -143'!E3+DLF!E3+'Faridabad Sec15'!E3+'Gurgaon Sec-15'!E3+'Gurgaon Sec - 10'!E3+'Paschim Vihar'!E3+Kalkaji!E3+CP!E3+Rohini!E3+'Model Town'!E3+'Pacific Mall'!E3 -> 1043813.5 | G4: ='Noida Sec - 18'!F3+'Noida Sec -143'!F3+DLF!F3+'Faridabad Sec15'!F3+'Gurgaon Sec-15'!F3+'Gurgaon Sec - 10'!F3+'Paschim Vihar'!F3+Kalkaji!F3+CP!F3+Rohini!F3+'Model Town'!F3+'Pacific Mall'!F3 -> 1053063.8 | H4: ='Noida Sec - 18'!G3+'Noida Sec -143'!G3+DLF!G3+'Faridabad Sec15'!G3+'Gurgaon Sec-15'!G3+'Gurgaon Sec - 10'!G3+'Paschim Vihar'!G3+Kalkaji!G3+CP!G3+Rohini!G3+'Model Town'!G3+'Pacific Mall'!G3 -> 931666.9 | I4: ='Noida Sec - 18'!H3+'Noida Sec -143'!H3+DLF!H3+'Faridabad Sec15'!H3+'Gurgaon Sec-15'!H3+'Gurgaon Sec - 10'!H3+'Paschim Vihar'!H3+Kalkaji!H3+CP!H3+Rohini!H3+'Model Town'!H3+'Pacific Mall'!H3 -> 970596.89 | J4: ='Noida Sec - 18'!I3+'Noida Sec -143'!I3+DLF!I3+'Faridabad Sec15'!I3+'Gurgaon Sec-15'!I3+'Gurgaon Sec - 10'!I3+'Paschim Vihar'!I3+Kalkaji!I3+CP!I3+Rohini!I3+'Model Town'!I3+'Pacific Mall'!I3 -> 977614.19 | ... N4: ='Noida Sec - 18'!M3+'Noida Sec -143'!M3+DLF!M3+'Faridabad Sec15'!M3+'Gurgaon Sec-15'!M3+'Gurgaon Sec - 10'!M3+'Paschim Vihar'!M3+Kalkaji!M3+CP!M3+Rohini!M3+'Model Town'!M3+'Pacific Mall'!M3 -> 850671.5
A5: Purchases Food (Less Purchase Return) | B5: Procurement | C5: ='Noida Sec - 18'!B4+'Noida Sec -143'!B4+'Faridabad Sec15'!B4+DLF!B4+'Gurgaon Sec-15'!B4+'Paschim Vihar'!B4+Kalkaji!B4+CP!B4+Rohini!B4+'Model Town'!B4+'Pacific Mall'!B4+480296 -> 4466945.2 | D5: ='Noida Sec - 18'!C4+'Noida Sec -143'!C4+'Faridabad Sec15'!C4+DLF!C4+'Gurgaon Sec-15'!C4+'Paschim Vihar'!C4+Kalkaji!C4+CP!C4+Rohini!C4+'Model Town'!C4+'Pacific Mall'!C4+238551 -> 4537965.8 | E5: ='Noida Sec - 18'!D4+'Noida Sec -143'!D4+'Faridabad Sec15'!D4+DLF!D4+'Gurgaon Sec-15'!D4+'Paschim Vihar'!D4+Kalkaji!D4+CP!D4+Rohini!D4+'Model Town'!D4+'Pacific Mall'!D4+267948 -> 4576663.5 | F5: ='Noida Sec - 18'!E4+'Noida Sec -143'!E4+'Faridabad Sec15'!E4+DLF!E4+'Gurgaon Sec-15'!E4+'Paschim Vihar'!E4+Kalkaji!E4+CP!E4+Rohini!E4+'Model Town'!E4+'Pacific Mall'!E4+113974 -> 4748672.2 | G5: ='Noida Sec - 18'!F4+'Noida Sec -143'!F4+'Faridabad Sec15'!F4+DLF!F4+'Gurgaon Sec-15'!F4+'Paschim Vihar'!F4+Kalkaji!F4+CP!F4+Rohini!F4+'Model Town'!F4+'Pacific Mall'!F4+160391 -> 4564517.1 | H5: ='Noida Sec - 18'!G4+'Noida Sec -143'!G4+'Faridabad Sec15'!G4+DLF!G4+'Gurgaon Sec-15'!G4+'Paschim Vihar'!G4+Kalkaji!G4+CP!G4+Rohini!G4+'Model Town'!G4+'Pacific Mall'!G4+515868 -> 4521500.6 | I5: ='Noida Sec - 18'!H4+'Noida Sec -143'!H4+'Faridabad Sec15'!H4+DLF!H4+'Gurgaon Sec-15'!H4+'Paschim Vihar'!H4+Kalkaji!H4+CP!H4+Rohini!H4+'Model Town'!H4+'Pacific Mall'!H4+184386 -> 3978759.1 | J5: ='Noida Sec - 18'!I4+'Noida Sec -143'!I4+'Faridabad Sec15'!I4+DLF!I4+'Gurgaon Sec-15'!I4+'Paschim Vihar'!I4+Kalkaji!I4+CP!I4+Rohini!I4+'Model Town'!I4+'Pacific Mall'!I4+283112 -> 4063531.4 | K5: ='Noida Sec - 18'!J4+'Noida Sec -143'!J4+'Faridabad Sec15'!J4+DLF!J4+'Gurgaon Sec-15'!J4+'Paschim Vihar'!J4+Kalkaji!J4+CP!J4+Rohini!J4+'Model Town'!J4+'Pacific Mall'!J4+'Gurgaon Sec - 10'!J4+105978 -> 4503673.6 | L5: ='Noida Sec - 18'!K4+'Noida Sec -143'!K4+'Faridabad Sec15'!K4+DLF!K4+'Gurgaon Sec-15'!K4+'Paschim Vihar'!K4+Kalkaji!K4+CP!K4+Rohini!K4+'Model Town'!K4+'Pacific Mall'!K4+'Gurgaon Sec - 10'!K4 -> 4550618.1 | M5: ='Noida Sec - 18'!L4+'Noida Sec -143'!L4+DLF!L4+'Faridabad Sec15'!L4+'Gurgaon Sec-15'!L4+'Gurgaon Sec - 10'!L4+'Paschim Vihar'!L4+Kalkaji!L4+CP!L4+Rohini!L4+'Model Town'!L4+'Pacific Mall'!L4+461000 -> 5135833.3 | N5: ='Noida Sec - 18'!M4+'Noida Sec -143'!M4+DLF!M4+'Faridabad Sec15'!M4+'Gurgaon Sec-15'!M4+'Gurgaon Sec - 10'!M4+'Paschim Vihar'!M4+Kalkaji!M4+CP!M4+Rohini!M4+'Model Town'!M4+'Pacific Mall'!M4+'Shalimar Bagh'!M4+114362 -> 5694719.4
A6: Transferred Out | B6: Procurement | C6: ='Noida Sec - 18'!B5+'Noida Sec -143'!B5+'Faridabad Sec15'!B5+DLF!B5+'Gurgaon Sec-15'!B5+'Paschim Vihar'!B5+Kalkaji!B5+CP!B5+Rohini!B5+'Model Town'!B5+'Pacific Mall'!B5 -> 0 | D6: ='Noida Sec - 18'!C5+'Noida Sec -143'!C5+'Faridabad Sec15'!C5+DLF!C5+'Gurgaon Sec-15'!C5+'Paschim Vihar'!C5+Kalkaji!C5+CP!C5+Rohini!C5+'Model Town'!C5+'Pacific Mall'!C5 -> 16172 | E6: ='Noida Sec - 18'!D5+'Noida Sec -143'!D5+'Faridabad Sec15'!D5+DLF!D5+'Gurgaon Sec-15'!D5+'Paschim Vihar'!D5+Kalkaji!D5+CP!D5+Rohini!D5+'Model Town'!D5+'Pacific Mall'!D5 -> 8649.27 | F6: ='Noida Sec - 18'!E5+'Noida Sec -143'!E5+'Faridabad Sec15'!E5+DLF!E5+'Gurgaon Sec-15'!E5+'Paschim Vihar'!E5+Kalkaji!E5+CP!E5+Rohini!E5+'Model Town'!E5+'Pacific Mall'!E5 -> 556 | G6: ='Noida Sec - 18'!F5+'Noida Sec -143'!F5+'Faridabad Sec15'!F5+DLF!F5+'Gurgaon Sec-15'!F5+'Paschim Vihar'!F5+Kalkaji!F5+CP!F5+Rohini!F5+'Model Town'!F5+'Pacific Mall'!F5 -> 0 | H6: ='Noida Sec - 18'!G5+'Noida Sec -143'!G5+'Faridabad Sec15'!G5+DLF!G5+'Gurgaon Sec-15'!G5+'Paschim Vihar'!G5+Kalkaji!G5+CP!G5+Rohini!G5+'Model Town'!G5+'Pacific Mall'!G5 -> 0 | I6: ='Noida Sec - 18'!H5+'Noida Sec -143'!H5+'Faridabad Sec15'!H5+DLF!H5+'Gurgaon Sec-15'!H5+'Paschim Vihar'!H5+Kalkaji!H5+CP!H5+Rohini!H5+'Model Town'!H5+'Pacific Mall'!H5 -> 0 | J6: ='Noida Sec - 18'!I5+'Noida Sec -143'!I5+'Faridabad Sec15'!I5+DLF!I5+'Gurgaon Sec-15'!I5+'Paschim Vihar'!I5+Kalkaji!I5+CP!I5+Rohini!I5+'Model Town'!I5+'Pacific Mall'!I5 -> 25336.42 | K6: ='Noida Sec - 18'!J5+'Noida Sec -143'!J5+'Faridabad Sec15'!J5+DLF!J5+'Gurgaon Sec-15'!J5+'Paschim Vihar'!J5+Kalkaji!J5+CP!J5+Rohini!J5+'Model Town'!J5+'Pacific Mall'!J5+'Gurgaon Sec - 10'!J5 -> 2081 | L6: ='Noida Sec - 18'!K5+'Noida Sec -143'!K5+'Faridabad Sec15'!K5+DLF!K5+'Gurgaon Sec-15'!K5+'Paschim Vihar'!K5+Kalkaji!K5+CP!K5+Rohini!K5+'Model Town'!K5+'Pacific Mall'!K5+'Gurgaon Sec - 10'!K5 -> 462.35 | M6: ='Noida Sec - 18'!L5+'Noida Sec -143'!L5+DLF!L5+'Faridabad Sec15'!L5+'Gurgaon Sec-15'!L5+'Gurgaon Sec - 10'!L5+'Paschim Vihar'!L5+Kalkaji!L5+CP!L5+Rohini!L5+'Model Town'!L5+'Pacific Mall'!L5 -> 43712 | N6: ='Noida Sec - 18'!M5+'Noida Sec -143'!M5+DLF!M5+'Faridabad Sec15'!M5+'Gurgaon Sec-15'!M5+'Gurgaon Sec - 10'!M5+'Paschim Vihar'!M5+Kalkaji!M5+CP!M5+Rohini!M5+'Model Town'!M5+'Pacific Mall'!M5+'Shalimar Bagh'!M5 -> 3114.98
A7: Wastage & Date Expired | B7: Procurement | C7: ='Noida Sec - 18'!B6+'Noida Sec -143'!B6+'Faridabad Sec15'!B6+DLF!B6+'Gurgaon Sec-15'!B6+'Paschim Vihar'!B6+Kalkaji!B6+CP!B6+Rohini!B6+'Model Town'!B6+'Pacific Mall'!B6 -> 257019 | D7: ='Noida Sec - 18'!C6+'Noida Sec -143'!C6+'Faridabad Sec15'!C6+DLF!C6+'Gurgaon Sec-15'!C6+'Paschim Vihar'!C6+Kalkaji!C6+CP!C6+Rohini!C6+'Model Town'!C6+'Pacific Mall'!C6 -> 272145.73 | E7: ='Noida Sec - 18'!D6+'Noida Sec -143'!D6+'Faridabad Sec15'!D6+DLF!D6+'Gurgaon Sec-15'!D6+'Paschim Vihar'!D6+Kalkaji!D6+CP!D6+Rohini!D6+'Model Town'!D6+'Pacific Mall'!D6 -> 250427.5 | F7: ='Noida Sec - 18'!E6+'Noida Sec -143'!E6+'Faridabad Sec15'!E6+DLF!E6+'Gurgaon Sec-15'!E6+'Paschim Vihar'!E6+Kalkaji!E6+CP!E6+Rohini!E6+'Model Town'!E6+'Pacific Mall'!E6 -> 268883.8 | G7: ='Noida Sec - 18'!F6+'Noida Sec -143'!F6+'Faridabad Sec15'!F6+DLF!F6+'Gurgaon Sec-15'!F6+'Paschim Vihar'!F6+Kalkaji!F6+CP!F6+Rohini!F6+'Model Town'!F6+'Pacific Mall'!F6 -> 267299.42 | H7: ='Noida Sec - 18'!G6+'Noida Sec -143'!G6+'Faridabad Sec15'!G6+DLF!G6+'Gurgaon Sec-15'!G6+'Paschim Vihar'!G6+Kalkaji!G6+CP!G6+Rohini!G6+'Model Town'!G6+'Pacific Mall'!G6 -> 254022.52 | I7: ='Noida Sec - 18'!H6+'Noida Sec -143'!H6+'Faridabad Sec15'!H6+DLF!H6+'Gurgaon Sec-15'!H6+'Paschim Vihar'!H6+Kalkaji!H6+CP!H6+Rohini!H6+'Model Town'!H6+'Pacific Mall'!H6 -> 270740.17 | J7: ='Noida Sec - 18'!I6+'Noida Sec -143'!I6+'Faridabad Sec15'!I6+DLF!I6+'Gurgaon Sec-15'!I6+'Paschim Vihar'!I6+Kalkaji!I6+CP!I6+Rohini!I6+'Model Town'!I6+'Pacific Mall'!I6 -> 300905.03 | K7: ='Noida Sec - 18'!J6+'Noida Sec -143'!J6+'Faridabad Sec15'!J6+DLF!J6+'Gurgaon Sec-15'!J6+'Paschim Vihar'!J6+Kalkaji!J6+CP!J6+Rohini!J6+'Model Town'!J6+'Pacific Mall'!J6+'Gurgaon Sec - 10'!J6 -> 291445.37 | L7: ='Noida Sec - 18'!K6+'Noida Sec -143'!K6+'Faridabad Sec15'!K6+DLF!K6+'Gurgaon Sec-15'!K6+'Paschim Vihar'!K6+Kalkaji!K6+CP!K6+Rohini!K6+'Model Town'!K6+'Pacific Mall'!K6+'Gurgaon Sec - 10'!K6 -> 285924.53 | M7: ='Noida Sec - 18'!L6+'Noida Sec -143'!L6+DLF!L6+'Faridabad Sec15'!L6+'Gurgaon Sec-15'!L6+'Gurgaon Sec - 10'!L6+'Paschim Vihar'!L6+Kalkaji!L6+CP!L6+Rohini!L6+'Model Town'!L6+'Pacific Mall'!L6 -> 296116.67 | N7: ='Noida Sec - 18'!M6+'Noida Sec -143'!M6+DLF!M6+'Faridabad Sec15'!M6+'Gurgaon Sec-15'!M6+'Gurgaon Sec - 10'!M6+'Paschim Vihar'!M6+Kalkaji!M6+CP!M6+Rohini!M6+'Model Town'!M6+'Pacific Mall'!M6+'Shalimar Bagh'!M6 -> 344801.16
A8: Closing Stock | B8: Procurement | C8: ='Noida Sec - 18'!B7+'Noida Sec -143'!B7+DLF!B7+'Faridabad Sec15'!B7+'Gurgaon Sec-15'!B7+'Gurgaon Sec - 10'!B7+'Paschim Vihar'!B7+Kalkaji!B7+CP!B7+Rohini!B7+'Model Town'!B7+'Pacific Mall'!B7 -> 976756 | D8: ='Noida Sec - 18'!C7+'Noida Sec -143'!C7+DLF!C7+'Faridabad Sec15'!C7+'Gurgaon Sec-15'!C7+'Gurgaon Sec - 10'!C7+'Paschim Vihar'!C7+Kalkaji!C7+CP!C7+Rohini!C7+'Model Town'!C7+'Pacific Mall'!C7 -> 1011915 | E8: ='Noida Sec - 18'!D7+'Noida Sec -143'!D7+DLF!D7+'Faridabad Sec15'!D7+'Gurgaon Sec-15'!D7+'Gurgaon Sec - 10'!D7+'Paschim Vihar'!D7+Kalkaji!D7+CP!D7+Rohini!D7+'Model Town'!D7+'Pacific Mall'!D7 -> 1043813.5 | F8: ='Noida Sec - 18'!E7+'Noida Sec -143'!E7+DLF!E7+'Faridabad Sec15'!E7+'Gurgaon Sec-15'!E7+'Gurgaon Sec - 10'!E7+'Paschim Vihar'!E7+Kalkaji!E7+CP!E7+Rohini!E7+'Model Town'!E7+'Pacific Mall'!E7 -> 1053063.8 | G8: ='Noida Sec - 18'!F7+'Noida Sec -143'!F7+DLF!F7+'Faridabad Sec15'!F7+'Gurgaon Sec-15'!F7+'Gurgaon Sec - 10'!F7+'Paschim Vihar'!F7+Kalkaji!F7+CP!F7+Rohini!F7+'Model Town'!F7+'Pacific Mall'!F7 -> 931666.9 | H8: ='Noida Sec - 18'!G7+'Noida Sec -143'!G7+DLF!G7+'Faridabad Sec15'!G7+'Gurgaon Sec-15'!G7+'Gurgaon Sec - 10'!G7+'Paschim Vihar'!G7+Kalkaji!G7+CP!G7+Rohini!G7+'Model Town'!G7+'Pacific Mall'!G7 -> 970596.89 | I8: ='Noida Sec - 18'!H7+'Noida Sec -143'!H7+DLF!H7+'Faridabad Sec15'!H7+'Gurgaon Sec-15'!H7+'Gurgaon Sec - 10'!H7+'Paschim Vihar'!H7+Kalkaji!H7+CP!H7+Rohini!H7+'Model Town'!H7+'Pacific Mall'!H7 -> 977614.19 | J8: ='Noida Sec - 18'!I7+'Noida Sec -143'!I7+DLF!I7+'Faridabad Sec15'!I7+'Gurgaon Sec-15'!I7+'Gurgaon Sec - 10'!I7+'Paschim Vihar'!I7+Kalkaji!I7+CP!I7+Rohini!I7+'Model Town'!I7+'Pacific Mall'!I7 -> 1023788.5 | ... M8: ='Noida Sec - 18'!L7+'Noida Sec -143'!L7+DLF!L7+'Faridabad Sec15'!L7+'Gurgaon Sec-15'!L7+'Gurgaon Sec - 10'!L7+'Paschim Vihar'!L7+Kalkaji!L7+CP!L7+Rohini!L7+'Model Town'!L7+'Pacific Mall'!L7 -> 847710.85 | N8: ='Noida Sec - 18'!M7+'Noida Sec -143'!M7+DLF!M7+'Faridabad Sec15'!M7+'Gurgaon Sec-15'!M7+'Gurgaon Sec - 10'!M7+'Paschim Vihar'!M7+Kalkaji!M7+CP!M7+Rohini!M7+'Model Town'!M7+'Pacific Mall'!M7+'Shalimar Bagh'!M7 -> 865957.47
A10: Gross Revenue | B10: Operation | C10: ='Noida Sec - 18'!B9+'Noida Sec -143'!B9+'Faridabad Sec15'!B9+DLF!B9+'Gurgaon Sec-15'!B9+'Paschim Vihar'!B9+Kalkaji!B9+CP!B9+Rohini!B9+'Model Town'!B9+'Pacific Mall'!B9+'Gurgaon Sec - 10'!B9+'Shalimar Bagh'!B9 -> 16506267 | D10: ='Noida Sec - 18'!C9+'Noida Sec -143'!C9+'Faridabad Sec15'!C9+DLF!C9+'Gurgaon Sec-15'!C9+'Paschim Vihar'!C9+Kalkaji!C9+CP!C9+Rohini!C9+'Model Town'!C9+'Pacific Mall'!C9+'Gurgaon Sec - 10'!C9+'Shalimar Bagh'!C9 -> 17850038 | E10: ='Noida Sec - 18'!D9+'Noida Sec -143'!D9+'Faridabad Sec15'!D9+DLF!D9+'Gurgaon Sec-15'!D9+'Paschim Vihar'!D9+Kalkaji!D9+CP!D9+Rohini!D9+'Model Town'!D9+'Pacific Mall'!D9+'Gurgaon Sec - 10'!D9+'Shalimar Bagh'!D9 -> 17762029 | F10: ='Noida Sec - 18'!E9+'Noida Sec -143'!E9+'Faridabad Sec15'!E9+DLF!E9+'Gurgaon Sec-15'!E9+'Paschim Vihar'!E9+Kalkaji!E9+CP!E9+Rohini!E9+'Model Town'!E9+'Pacific Mall'!E9+'Gurgaon Sec - 10'!E9+'Shalimar Bagh'!E9 -> 18827858 | G10: ='Noida Sec - 18'!F9+'Noida Sec -143'!F9+'Faridabad Sec15'!F9+DLF!F9+'Gurgaon Sec-15'!F9+'Paschim Vihar'!F9+Kalkaji!F9+CP!F9+Rohini!F9+'Model Town'!F9+'Pacific Mall'!F9+'Gurgaon Sec - 10'!F9+'Shalimar Bagh'!F9 -> 18611135 | H10: ='Noida Sec - 18'!G9+'Noida Sec -143'!G9+'Faridabad Sec15'!G9+DLF!G9+'Gurgaon Sec-15'!G9+'Paschim Vihar'!G9+Kalkaji!G9+CP!G9+Rohini!G9+'Model Town'!G9+'Pacific Mall'!G9+'Gurgaon Sec - 10'!G9+'Shalimar Bagh'!G9 -> 16760496 | I10: ='Noida Sec - 18'!H9+'Noida Sec -143'!H9+'Faridabad Sec15'!H9+DLF!H9+'Gurgaon Sec-15'!H9+'Paschim Vihar'!H9+Kalkaji!H9+CP!H9+Rohini!H9+'Model Town'!H9+'Pacific Mall'!H9+'Gurgaon Sec - 10'!H9+'Shalimar Bagh'!H9 -> 16220749 | J10: ='Noida Sec - 18'!I9+'Noida Sec -143'!I9+'Faridabad Sec15'!I9+DLF!I9+'Gurgaon Sec-15'!I9+'Paschim Vihar'!I9+Kalkaji!I9+CP!I9+Rohini!I9+'Model Town'!I9+'Pacific Mall'!I9+'Gurgaon Sec - 10'!I9+'Shalimar Bagh'!I9 -> 16064434 | ... N10: ='Noida Sec - 18'!M9+'Noida Sec -143'!M9+'Faridabad Sec15'!M9+DLF!M9+'Gurgaon Sec-15'!M9+'Paschim Vihar'!M9+Kalkaji!M9+CP!M9+Rohini!M9+'Model Town'!M9+'Pacific Mall'!M9+'Gurgaon Sec - 10'!M9+'Shalimar Bagh'!M9 -> 23420696 | O10: =+SUM(C10:N10) -> 2.192413e+08
A11: Catering & Fairs | B11: Operation | C11: ='Noida Sec - 18'!B10+'Noida Sec -143'!B10+'Faridabad Sec15'!B10+DLF!B10+'Gurgaon Sec-15'!B10+'Paschim Vihar'!B10+Kalkaji!B10+CP!B10+Rohini!B10+'Model Town'!B10+'Pacific Mall'!B10 -> 0 | D11: ='Noida Sec - 18'!C10+'Noida Sec -143'!C10+'Faridabad Sec15'!C10+DLF!C10+'Gurgaon Sec-15'!C10+'Paschim Vihar'!C10+Kalkaji!C10+CP!C10+Rohini!C10+'Model Town'!C10+'Pacific Mall'!C10 -> 0 | E11: ='Noida Sec - 18'!D10+'Noida Sec -143'!D10+'Faridabad Sec15'!D10+DLF!D10+'Gurgaon Sec-15'!D10+'Paschim Vihar'!D10+Kalkaji!D10+CP!D10+Rohini!D10+'Model Town'!D10+'Pacific Mall'!D10 -> 34020 | F11: ='Noida Sec - 18'!E10+'Noida Sec -143'!E10+'Faridabad Sec15'!E10+DLF!E10+'Gurgaon Sec-15'!E10+'Paschim Vihar'!E10+Kalkaji!E10+CP!E10+Rohini!E10+'Model Town'!E10+'Pacific Mall'!E10 -> 0 | G11: ='Noida Sec - 18'!F10+'Noida Sec -143'!F10+'Faridabad Sec15'!F10+DLF!F10+'Gurgaon Sec-15'!F10+'Paschim Vihar'!F10+Kalkaji!F10+CP!F10+Rohini!F10+'Model Town'!F10+'Pacific Mall'!F10 -> 0 | H11: ='Noida Sec - 18'!G10+'Noida Sec -143'!G10+'Faridabad Sec15'!G10+DLF!G10+'Gurgaon Sec-15'!G10+'Paschim Vihar'!G10+Kalkaji!G10+CP!G10+Rohini!G10+'Model Town'!G10+'Pacific Mall'!G10 -> 0 | I11: ='Noida Sec - 18'!H10+'Noida Sec -143'!H10+'Faridabad Sec15'!H10+DLF!H10+'Gurgaon Sec-15'!H10+'Paschim Vihar'!H10+Kalkaji!H10+CP!H10+Rohini!H10+'Model Town'!H10+'Pacific Mall'!H10 -> 0 | J11: ='Noida Sec - 18'!I10+'Noida Sec -143'!I10+'Faridabad Sec15'!I10+DLF!I10+'Gurgaon Sec-15'!I10+'Paschim Vihar'!I10+Kalkaji!I10+CP!I10+Rohini!I10+'Model Town'!I10+'Pacific Mall'!I10 -> 0 | K11: ='Noida Sec - 18'!J10+'Noida Sec -143'!J10+'Faridabad Sec15'!J10+DLF!J10+'Gurgaon Sec-15'!J10+'Paschim Vihar'!J10+Kalkaji!J10+CP!J10+Rohini!J10+'Model Town'!J10+'Pacific Mall'!J10+'Gurgaon Sec - 10'!J10 -> 0 | L11: ='Noida Sec - 18'!K10+'Noida Sec -143'!K10+'Faridabad Sec15'!K10+DLF!K10+'Gurgaon Sec-15'!K10+'Paschim Vihar'!K10+Kalkaji!K10+CP!K10+Rohini!K10+'Model Town'!K10+'Pacific Mall'!K10 -> 0 | M11: ='Noida Sec - 18'!L10+'Noida Sec -143'!L10+'Faridabad Sec15'!L10+DLF!L10+'Gurgaon Sec-15'!L10+'Paschim Vihar'!L10+Kalkaji!L10+CP!L10+Rohini!L10+'Model Town'!L10+'Pacific Mall'!L10+'Gurgaon Sec - 10'!L10+'Shalimar Bagh'!L10 -> 0 | N11: ='Noida Sec - 18'!M10+'Noida Sec -143'!M10+'Faridabad Sec15'!M10+DLF!M10+'Gurgaon Sec-15'!M10+'Paschim Vihar'!M10+Kalkaji!M10+CP!M10+Rohini!M10+'Model Town'!M10+'Pacific Mall'!M10+'Gurgaon Sec - 10'!M10+'Shalimar Bagh'!M10 -> 0 | O11: =+SUM(C11:N11) -> 34020
A12: Less Tax | B12: Operation | C12: ='Noida Sec - 18'!B11+'Noida Sec -143'!B11+'Faridabad Sec15'!B11+DLF!B11+'Gurgaon Sec-15'!B11+'Paschim Vihar'!B11+Kalkaji!B11+CP!B11+Rohini!B11+'Model Town'!B11+'Pacific Mall'!B11 -> 786012.7 | D12: ='Noida Sec - 18'!C11+'Noida Sec -143'!C11+'Faridabad Sec15'!C11+DLF!C11+'Gurgaon Sec-15'!C11+'Paschim Vihar'!C11+Kalkaji!C11+CP!C11+Rohini!C11+'Model Town'!C11+'Pacific Mall'!C11 -> 850001.81 | E12: ='Noida Sec - 18'!D11+'Noida Sec -143'!D11+'Faridabad Sec15'!D11+DLF!D11+'Gurgaon Sec-15'!D11+'Paschim Vihar'!D11+Kalkaji!D11+CP!D11+Rohini!D11+'Model Town'!D11+'Pacific Mall'!D11 -> 847430.88 | F12: ='Noida Sec - 18'!E11+'Noida Sec -143'!E11+'Faridabad Sec15'!E11+DLF!E11+'Gurgaon Sec-15'!E11+'Paschim Vihar'!E11+Kalkaji!E11+CP!E11+Rohini!E11+'Model Town'!E11+'Pacific Mall'!E11 -> 896564.69 | G12: ='Noida Sec - 18'!F11+'Noida Sec -143'!F11+'Faridabad Sec15'!F11+DLF!F11+'Gurgaon Sec-15'!F11+'Paschim Vihar'!F11+Kalkaji!F11+CP!F11+Rohini!F11+'Model Town'!F11+'Pacific Mall'!F11 -> 886244.52 | H12: ='Noida Sec - 18'!G11+'Noida Sec -143'!G11+'Faridabad Sec15'!G11+DLF!G11+'Gurgaon Sec-15'!G11+'Paschim Vihar'!G11+Kalkaji!G11+CP!G11+Rohini!G11+'Model Town'!G11+'Pacific Mall'!G11 -> 798118.86 | I12: ='Noida Sec - 18'!H11+'Noida Sec -143'!H11+'Faridabad Sec15'!H11+DLF!H11+'Gurgaon Sec-15'!H11+'Paschim Vihar'!H11+Kalkaji!H11+CP!H11+Rohini!H11+'Model Town'!H11+'Pacific Mall'!H11 -> 772416.64 | J12: ='Noida Sec - 18'!I11+'Noida Sec -143'!I11+'Faridabad Sec15'!I11+DLF!I11+'Gurgaon Sec-15'!I11+'Paschim Vihar'!I11+Kalkaji!I11+CP!I11+Rohini!I11+'Model Town'!I11+'Pacific Mall'!I11 -> 764973.06 | K12: ='Noida Sec - 18'!J11+'Noida Sec -143'!J11+'Faridabad Sec15'!J11+DLF!J11+'Gurgaon Sec-15'!J11+'Paschim Vihar'!J11+Kalkaji!J11+CP!J11+Rohini!J11+'Model Town'!J11+'Pacific Mall'!J11+'Gurgaon Sec - 10'!J11 -> 808781.85 | L12: ='Noida Sec - 18'!K11+'Noida Sec -143'!K11+'Faridabad Sec15'!K11+DLF!K11+'Gurgaon Sec-15'!K11+'Paschim Vihar'!K11+Kalkaji!K11+CP!K11+Rohini!K11+'Model Town'!K11+'Pacific Mall'!K11 -> 920371.85 | M12: ='Noida Sec - 18'!L11+'Noida Sec -143'!L11+'Faridabad Sec15'!L11+DLF!L11+'Gurgaon Sec-15'!L11+'Paschim Vihar'!L11+Kalkaji!L11+CP!L11+Rohini!L11+'Model Town'!L11+'Pacific Mall'!L11+'Gurgaon Sec - 10'!L11+'Shalimar Bagh'!L11 -> 962717.84 | N12: ='Noida Sec - 18'!M11+'Noida Sec -143'!M11+'Faridabad Sec15'!M11+DLF!M11+'Gurgaon Sec-15'!M11+'Paschim Vihar'!M11+Kalkaji!M11+CP!M11+Rohini!M11+'Model Town'!M11+'Pacific Mall'!M11+'Gurgaon Sec - 10'!M11+'Shalimar Bagh'!M11 -> 1115271.2 | O12: =+SUM(C12:N12) -> 10408906
A13: Less Commission | B13: Operation | C13: ='Noida Sec - 18'!B12+'Noida Sec -143'!B12+'Faridabad Sec15'!B12+DLF!B12+'Gurgaon Sec-15'!B12+'Paschim Vihar'!B12+Kalkaji!B12+CP!B12+Rohini!B12+'Model Town'!B12+'Pacific Mall'!B12 -> 1017799.9 | D13: ='Noida Sec - 18'!C12+'Noida Sec -143'!C12+'Faridabad Sec15'!C12+DLF!C12+'Gurgaon Sec-15'!C12+'Paschim Vihar'!C12+Kalkaji!C12+CP!C12+Rohini!C12+'Model Town'!C12+'Pacific Mall'!C12 -> 1203038 | E13: ='Noida Sec - 18'!D12+'Noida Sec -143'!D12+'Faridabad Sec15'!D12+DLF!D12+'Gurgaon Sec-15'!D12+'Paschim Vihar'!D12+Kalkaji!D12+CP!D12+Rohini!D12+'Model Town'!D12+'Pacific Mall'!D12 -> 1241370.1 | F13: ='Noida Sec - 18'!E12+'Noida Sec -143'!E12+'Faridabad Sec15'!E12+DLF!E12+'Gurgaon Sec-15'!E12+'Paschim Vihar'!E12+Kalkaji!E12+CP!E12+Rohini!E12+'Model Town'!E12+'Pacific Mall'!E12 -> 1406953.7 | G13: ='Noida Sec - 18'!F12+'Noida Sec -143'!F12+'Faridabad Sec15'!F12+DLF!F12+'Gurgaon Sec-15'!F12+'Paschim Vihar'!F12+Kalkaji!F12+CP!F12+Rohini!F12+'Model Town'!F12+'Pacific Mall'!F12 -> 1282423.1 | H13: ='Noida Sec - 18'!G12+'Noida Sec -143'!G12+'Faridabad Sec15'!G12+DLF!G12+'Gurgaon Sec-15'!G12+'Paschim Vihar'!G12+Kalkaji!G12+CP!G12+Rohini!G12+'Model Town'!G12+'Pacific Mall'!G12 -> 1162069.4 | I13: ='Noida Sec - 18'!H12+'Noida Sec -143'!H12+'Faridabad Sec15'!H12+DLF!H12+'Gurgaon Sec-15'!H12+'Paschim Vihar'!H12+Kalkaji!H12+CP!H12+Rohini!H12+'Model Town'!H12+'Pacific Mall'!H12 -> 1165725.8 | J13: ='Noida Sec - 18'!I12+'Noida Sec -143'!I12+'Faridabad Sec15'!I12+DLF!I12+'Gurgaon Sec-15'!I12+'Paschim Vihar'!I12+Kalkaji!I12+CP!I12+Rohini!I12+'Model Town'!I12+'Pacific Mall'!I12 -> 1060975.2 | K13: ='Noida Sec - 18'!J12+'Noida Sec -143'!J12+'Faridabad Sec15'!J12+DLF!J12+'Gurgaon Sec-15'!J12+'Paschim Vihar'!J12+Kalkaji!J12+CP!J12+Rohini!J12+'Model Town'!J12+'Pacific Mall'!J12+'Gurgaon Sec - 10'!J12 -> 1081776.9 | L13: ='Noida Sec - 18'!K12+'Noida Sec -143'!K12+DLF!K12+'Faridabad Sec15'!K12+'Gurgaon Sec-15'!K12+'Gurgaon Sec - 10'!K12+'Paschim Vihar'!K12+Kalkaji!K12+CP!K12+Rohini!K12+'Model Town'!K12+'Pacific Mall'!K12 -> 1296527.2 | M13: ='Noida Sec - 18'!L12+'Noida Sec -143'!L12+DLF!L12+'Faridabad Sec15'!L12+'Gurgaon Sec-15'!L12+'Gurgaon Sec - 10'!L12+'Paschim Vihar'!L12+Kalkaji!L12+CP!L12+Rohini!L12+'Model Town'!L12+'Pacific Mall'!L12 -> 1344867.6 | N13: ='Noida Sec - 18'!M12+'Noida Sec -143'!M12+'Faridabad Sec15'!M12+DLF!M12+'Gurgaon Sec-15'!M12+'Paschim Vihar'!M12+Kalkaji!M12+CP!M12+Rohini!M12+'Model Town'!M12+'Pacific Mall'!M12+'Gurgaon Sec - 10'!M12+'Shalimar Bagh'!M12 -> 1826332.2 | O13: =+SUM(C13:N13) -> 15089859
A14: Commission % | C14: =C13/C10 -> 0.061661423 | D14: =D13/D10 -> 0.067396945 | E14: =E13/E10 -> 0.069888982 | F14: =F13/F10 -> 0.074727229 | G14: =G13/G10 -> 0.068906226 | H14: =H13/H10 -> 0.069333833 | I14: =I13/I10 -> 0.071866333 | J14: =J13/J10 -> 0.066044974 | ... M14: =M13/M10 -> 0.066521374 | N14: =N13/(N10-N12) -> 0.081878387
A15: Net Revenues from F&B Sales | C15: =C10+C11-C12-C13 -> 14702454 | D15: =D10+D11-D12-D13 -> 15796998 | E15: =E10+E11-E12-E13 -> 15707248 | F15: =F10+F11-F12-F13 -> 16524340 | G15: =G10+G11-G12-G13 -> 16442467 | H15: =H10+H11-H12-H13 -> 14800308 | I15: =I10+I11-I12-I13 -> 14282607 | J15: =J10+J11-J12-J13 -> 14238486 | ... N15: =N10+N11-N12-N13 -> 20479092 | O15: =sum(C15:N15) -> 1.9377656e+08 | P15: =O15/$O$15 -> 1 | Q15: Average
A16: F&B Cost | B16: Operation | C16: =C4+C5-C6-C8 -> 4483905.2 | D16: =D4+D5-D6-D8 -> 4495472.2 | E16: =E4+E5-E6-E8 -> 4536115.7 | F16: =F4+F5-F6-F8 -> 4738866 | G16: =G4+G5-G6-G8 -> 4685914 | H16: =H4+H5-H6-H8 -> 4482570.6 | I16: =I4+I5-I6-I8 -> 3971741.8 | J16: =J4+J5-J6-J8 -> 3992020.6 | ... N16: =N4+N5-N6-N8 -> 5676318.5 | O16: =sum(C16:N16) -> 55382872 | P16: =O16/$O$15 -> 0.28580791 | Q16: =AVERAGE(C16:N16)/11 -> 419567.21
A17: Electricity | B17: Operation | C17: ='Noida Sec - 18'!B15+'Noida Sec -143'!B15+'Faridabad Sec15'!B15+DLF!B15+'Gurgaon Sec-15'!B15+'Paschim Vihar'!B15+Kalkaji!B15+CP!B15+Rohini!B15+'Model Town'!B15+'Pacific Mall'!B15 -> 976118.67 | D17: ='Noida Sec - 18'!C15+'Noida Sec -143'!C15+'Faridabad Sec15'!C15+DLF!C15+'Gurgaon Sec-15'!C15+'Paschim Vihar'!C15+Kalkaji!C15+CP!C15+Rohini!C15+'Model Town'!C15+'Pacific Mall'!C15 -> 1053906.5 | E17: ='Noida Sec - 18'!D15+'Noida Sec -143'!D15+'Faridabad Sec15'!D15+DLF!D15+'Gurgaon Sec-15'!D15+'Paschim Vihar'!D15+Kalkaji!D15+CP!D15+Rohini!D15+'Model Town'!D15+'Pacific Mall'!D15 -> 1205832.4 | F17: ='Noida Sec - 18'!E15+'Noida Sec -143'!E15+'Faridabad Sec15'!E15+DLF!E15+'Gurgaon Sec-15'!E15+'Paschim Vihar'!E15+Kalkaji!E15+CP!E15+Rohini!E15+'Model Town'!E15+'Pacific Mall'!E15 -> 1161765.2 | G17: ='Noida Sec - 18'!F15+'Noida Sec -143'!F15+'Faridabad Sec15'!F15+DLF!F15+'Gurgaon Sec-15'!F15+'Paschim Vihar'!F15+Kalkaji!F15+CP!F15+Rohini!F15+'Model Town'!F15+'Pacific Mall'!F15 -> 1099231.8 | H17: ='Noida Sec - 18'!G15+'Noida Sec -143'!G15+'Faridabad Sec15'!G15+DLF!G15+'Gurgaon Sec-15'!G15+'Paschim Vihar'!G15+Kalkaji!G15+CP!G15+Rohini!G15+'Model Town'!G15+'Pacific Mall'!G15 -> 1034760.3 | I17: ='Noida Sec -143'!H15+'Noida Sec -143'!H15+'Faridabad Sec15'!H15+DLF!H15+'Gurgaon Sec-15'!H15+'Paschim Vihar'!H15+Kalkaji!H15+CP!H15+Rohini!H15+'Model Town'!H15+'Pacific Mall'!H15 -> 1013794.2 | J17: ='Noida Sec - 18'!I15+'Noida Sec -143'!I15+'Faridabad Sec15'!I15+DLF!I15+'Gurgaon Sec-15'!I15+'Paschim Vihar'!I15+Kalkaji!I15+CP!I15+Rohini!I15+'Model Town'!I15+'Pacific Mall'!I15 -> 798388.74 | K17: ='Noida Sec - 18'!J15+'Noida Sec -143'!J15+'Faridabad Sec15'!J15+DLF!J15+'Gurgaon Sec-15'!J15+'Paschim Vihar'!J15+Kalkaji!J15+CP!J15+Rohini!J15+'Model Town'!J15+'Pacific Mall'!J15+'Gurgaon Sec - 10'!J15 -> 794077.74 | L17: ='Noida Sec - 18'!K15+'Noida Sec -143'!K15+DLF!K15+'Faridabad Sec15'!K15+'Gurgaon Sec-15'!K15+'Gurgaon Sec - 10'!K15+'Paschim Vihar'!K15+Kalkaji!K15+CP!K15+Rohini!K15+'Model Town'!K15+'Pacific Mall'!K15 -> 854411 | M17: ='Noida Sec - 18'!L15+'Noida Sec -143'!L15+DLF!L15+'Faridabad Sec15'!L15+'Gurgaon Sec-15'!L15+'Gurgaon Sec - 10'!L15+'Paschim Vihar'!L15+Kalkaji!L15+CP!L15+Rohini!L15+'Model Town'!L15+'Pacific Mall'!L15 -> 827419.9 | N17: ='Noida Sec - 18'!M15+'Noida Sec -143'!M15+DLF!M15+'Faridabad Sec15'!M15+'Gurgaon Sec-15'!M15+'Gurgaon Sec - 10'!M15+'Paschim Vihar'!M15+Kalkaji!M15+CP!M15+Rohini!M15+'Model Town'!M15+'Pacific Mall'!M15 -> 960724.29 | O17: =sum(C17:N17) -> 11780431 | P17: =O17/$O$15 -> 0.06079389 | Q17: =AVERAGE(C17:N17)/11 -> 89245.687
A18: Telephone/Internet | B18: Operation | C18: ='Noida Sec - 18'!B16+'Noida Sec -143'!B16+'Faridabad Sec15'!B16+DLF!B16+'Gurgaon Sec-15'!B16+'Paschim Vihar'!B16+Kalkaji!B16+CP!B16+Rohini!B16+'Model Town'!B16+'Pacific Mall'!B16 -> 16363 | D18: ='Noida Sec - 18'!C16+'Noida Sec -143'!C16+'Faridabad Sec15'!C16+DLF!C16+'Gurgaon Sec-15'!C16+'Paschim Vihar'!C16+Kalkaji!C16+CP!C16+Rohini!C16+'Model Town'!C16+'Pacific Mall'!C16 -> 12493 | E18: ='Noida Sec - 18'!D16+'Noida Sec -143'!D16+'Faridabad Sec15'!D16+DLF!D16+'Gurgaon Sec-15'!D16+'Paschim Vihar'!D16+Kalkaji!D16+CP!D16+Rohini!D16+'Model Town'!D16+'Pacific Mall'!D16 -> 16726 | F18: ='Noida Sec - 18'!E16+'Noida Sec -143'!E16+'Faridabad Sec15'!E16+DLF!E16+'Gurgaon Sec-15'!E16+'Paschim Vihar'!E16+Kalkaji!E16+CP!E16+Rohini!E16+'Model Town'!E16+'Pacific Mall'!E16 -> 14739.667 | G18: ='Noida Sec - 18'!F16+'Noida Sec -143'!F16+'Faridabad Sec15'!F16+DLF!F16+'Gurgaon Sec-15'!F16+'Paschim Vihar'!F16+Kalkaji!F16+CP!F16+Rohini!F16+'Model Town'!F16+'Pacific Mall'!F16 -> 21453.667 | H18: ='Noida Sec - 18'!G16+'Noida Sec -143'!G16+'Faridabad Sec15'!G16+DLF!G16+'Gurgaon Sec-15'!G16+'Paschim Vihar'!G16+Kalkaji!G16+CP!G16+Rohini!G16+'Model Town'!G16+'Pacific Mall'!G16 -> 17236.5 | I18: ='Noida Sec - 18'!H16+'Noida Sec -143'!H16+'Faridabad Sec15'!H16+DLF!H16+'Gurgaon Sec-15'!H16+'Paschim Vihar'!H16+Kalkaji!H16+CP!H16+Rohini!H16+'Model Town'!H16+'Pacific Mall'!H16 -> 16714.5 | J18: ='Noida Sec - 18'!I16+'Noida Sec -143'!I16+'Faridabad Sec15'!I16+DLF!I16+'Gurgaon Sec-15'!I16+'Paschim Vihar'!I16+Kalkaji!I16+CP!I16+Rohini!I16+'Model Town'!I16+'Pacific Mall'!I16 -> 16551.5 | K18: ='Noida Sec - 18'!J16+'Noida Sec -143'!J16+'Faridabad Sec15'!J16+DLF!J16+'Gurgaon Sec-15'!J16+'Paschim Vihar'!J16+Kalkaji!J16+CP!J16+Rohini!J16+'Model Town'!J16+'Pacific Mall'!J16+'Gurgaon Sec - 10'!J16 -> 18700.5 | L18: ='Noida Sec - 18'!K16+'Noida Sec -143'!K16+DLF!K16+'Faridabad Sec15'!K16+'Gurgaon Sec-15'!K16+'Gurgaon Sec - 10'!K16+'Paschim Vihar'!K16+Kalkaji!K16+CP!K16+Rohini!K16+'Model Town'!K16+'Pacific Mall'!K16 -> 17293 | M18: ='Noida Sec - 18'!L16+'Noida Sec -143'!L16+DLF!L16+'Faridabad Sec15'!L16+'Gurgaon Sec-15'!L16+'Gurgaon Sec - 10'!L16+'Paschim Vihar'!L16+Kalkaji!L16+CP!L16+Rohini!L16+'Model Town'!L16+'Pacific Mall'!L16 -> 17963.333 | N18: ='Noida Sec - 18'!M16+'Noida Sec -143'!M16+DLF!M16+'Faridabad Sec15'!M16+'Gurgaon Sec-15'!M16+'Gurgaon Sec - 10'!M16+'Paschim Vihar'!M16+Kalkaji!M16+CP!M16+Rohini!M16+'Model Town'!M16+'Pacific Mall'!M16 -> 16958.833 | O18: =sum(C18:N18) -> 203193.5 | P18: =O18/$O$15 -> 0.0010485969 | Q18: =AVERAGE(C18:N18)/11 -> 1539.3447
A19: Gas | B19: Operation | C19: ='Noida Sec - 18'!B17+'Noida Sec -143'!B17+'Faridabad Sec15'!B17+DLF!B17+'Gurgaon Sec-15'!B17+'Paschim Vihar'!B17+Kalkaji!B17+CP!B17+Rohini!B17+'Model Town'!B17+'Pacific Mall'!B17 -> 457528.12 | D19: ='Noida Sec - 18'!C17+'Noida Sec -143'!C17+'Faridabad Sec15'!C17+DLF!C17+'Gurgaon Sec-15'!C17+'Paschim Vihar'!C17+Kalkaji!C17+CP!C17+Rohini!C17+'Model Town'!C17+'Pacific Mall'!C17 -> 467109.22 | E19: ='Noida Sec - 18'!D17+'Noida Sec -143'!D17+'Faridabad Sec15'!D17+DLF!D17+'Gurgaon Sec-15'!D17+'Paschim Vihar'!D17+Kalkaji!D17+CP!D17+Rohini!D17+'Model Town'!D17+'Pacific Mall'!D17 -> 412683 | F19: ='Noida Sec - 18'!E17+'Noida Sec -143'!E17+'Faridabad Sec15'!E17+DLF!E17+'Gurgaon Sec-15'!E17+'Paschim Vihar'!E17+Kalkaji!E17+CP!E17+Rohini!E17+'Model Town'!E17+'Pacific Mall'!E17 -> 462577.07 | G19: ='Noida Sec - 18'!F17+'Noida Sec -143'!F17+'Faridabad Sec15'!F17+DLF!F17+'Gurgaon Sec-15'!F17+'Paschim Vihar'!F17+Kalkaji!F17+CP!F17+Rohini!F17+'Model Town'!F17+'Pacific Mall'!F17 -> 460647.17 | H19: ='Noida Sec - 18'!G17+'Noida Sec -143'!G17+'Faridabad Sec15'!G17+DLF!G17+'Gurgaon Sec-15'!G17+'Paschim Vihar'!G17+Kalkaji!G17+CP!G17+Rohini!G17+'Model Town'!G17+'Pacific Mall'!G17 -> 388897.66 | I19: ='Noida Sec - 18'!H17+'Noida Sec -143'!H17+'Faridabad Sec15'!H17+DLF!H17+'Gurgaon Sec-15'!H17+'Paschim Vihar'!H17+Kalkaji!H17+CP!H17+Rohini!H17+'Model Town'!H17+'Pacific Mall'!H17 -> 410212.91 | J19: ='Noida Sec - 18'!I17+'Noida Sec -143'!I17+'Faridabad Sec15'!I17+DLF!I17+'Gurgaon Sec-15'!I17+'Paschim Vihar'!I17+Kalkaji!I17+CP!I17+Rohini!I17+'Model Town'!I17+'Pacific Mall'!I17 -> 411242.41 | K19: ='Noida Sec - 18'!J17+'Noida Sec -143'!J17+'Faridabad Sec15'!J17+DLF!J17+'Gurgaon Sec-15'!J17+'Paschim Vihar'!J17+Kalkaji!J17+CP!J17+Rohini!J17+'Model Town'!J17+'Pacific Mall'!J17+'Gurgaon Sec - 10'!J17 -> 414262.84 | L19: ='Noida Sec - 18'!K17+'Noida Sec -143'!K17+DLF!K17+'Faridabad Sec15'!K17+'Gurgaon Sec-15'!K17+'Gurgaon Sec - 10'!K17+'Paschim Vihar'!K17+Kalkaji!K17+CP!K17+Rohini!K17+'Model Town'!K17+'Pacific Mall'!K17 -> 469708.5 | M19: ='Noida Sec - 18'!L17+'Noida Sec -143'!L17+DLF!L17+'Faridabad Sec15'!L17+'Gurgaon Sec-15'!L17+'Gurgaon Sec - 10'!L17+'Paschim Vihar'!L17+Kalkaji!L17+CP!L17+Rohini!L17+'Model Town'!L17+'Pacific Mall'!L17 -> 414365 | N19: ='Noida Sec - 18'!M17+'Noida Sec -143'!M17+DLF!M17+'Faridabad Sec15'!M17+'Gurgaon Sec-15'!M17+'Gurgaon Sec - 10'!M17+'Paschim Vihar'!M17+Kalkaji!M17+CP!M17+Rohini!M17+'Model Town'!M17+'Pacific Mall'!M17 -> 569160.5 | O19: =sum(C19:N19) -> 5338394.4 | P19: =O19/$O$15 -> 0.027549227 | Q19: =AVERAGE(C19:N19)/11 -> 40442.382
A20: Rent & Revenue Share | B20: Accounts | C20: ='Noida Sec - 18'!B18+'Noida Sec -143'!B18+'Faridabad Sec15'!B18+DLF!B18+'Gurgaon Sec-15'!B18+'Paschim Vihar'!B18+Kalkaji!B18+CP!B18+Rohini!B18+'Model Town'!B18+'Pacific Mall'!B18 -> 3613825.5 | D20: ='Noida Sec - 18'!C18+'Noida Sec -143'!C18+'Faridabad Sec15'!C18+DLF!C18+'Gurgaon Sec-15'!C18+'Paschim Vihar'!C18+Kalkaji!C18+CP!C18+Rohini!C18+'Model Town'!C18+'Pacific Mall'!C18 -> 3770381.3 | E20: ='Noida Sec - 18'!D18+'Noida Sec -143'!D18+'Faridabad Sec15'!D18+DLF!D18+'Gurgaon Sec-15'!D18+'Paschim Vihar'!D18+Kalkaji!D18+CP!D18+Rohini!D18+'Model Town'!D18+'Pacific Mall'!D18 -> 3770380.5 | F20: ='Noida Sec - 18'!E18+'Noida Sec -143'!E18+'Faridabad Sec15'!E18+DLF!E18+'Gurgaon Sec-15'!E18+'Paschim Vihar'!E18+Kalkaji!E18+CP!E18+Rohini!E18+'Model Town'!E18+'Pacific Mall'!E18 -> 3770380 | G20: ='Noida Sec - 18'!F18+'Noida Sec -143'!F18+'Faridabad Sec15'!F18+DLF!F18+'Gurgaon Sec-15'!F18+'Paschim Vihar'!F18+Kalkaji!F18+CP!F18+Rohini!F18+'Model Town'!F18+'Pacific Mall'!F18 -> 3770381.3 | H20: ='Noida Sec - 18'!G18+'Noida Sec -143'!G18+'Faridabad Sec15'!G18+DLF!G18+'Gurgaon Sec-15'!G18+'Paschim Vihar'!G18+Kalkaji!G18+CP!G18+Rohini!G18+'Model Town'!G18+'Pacific Mall'!G18 -> 3770380.5 | I20: ='Noida Sec - 18'!H18+'Noida Sec -143'!H18+'Faridabad Sec15'!H18+DLF!H18+'Gurgaon Sec-15'!H18+'Paschim Vihar'!H18+Kalkaji!H18+CP!H18+Rohini!H18+'Model Town'!H18+'Pacific Mall'!H18 -> 3770381 | J20: ='Noida Sec - 18'!I18+'Noida Sec -143'!I18+'Faridabad Sec15'!I18+DLF!I18+'Gurgaon Sec-15'!I18+'Paschim Vihar'!I18+Kalkaji!I18+CP!I18+Rohini!I18+'Model Town'!I18+'Pacific Mall'!I18 -> 3770381.3 | K20: ='Noida Sec - 18'!J18+'Noida Sec -143'!J18+'Faridabad Sec15'!J18+DLF!J18+'Gurgaon Sec-15'!J18+'Paschim Vihar'!J18+Kalkaji!J18+CP!J18+Rohini!J18+'Model Town'!J18+'Pacific Mall'!J18+'Gurgaon Sec - 10'!J18 -> 3759303.3 | L20: ='Noida Sec - 18'!K18+'Noida Sec -143'!K18+DLF!K18+'Faridabad Sec15'!K18+'Gurgaon Sec-15'!K18+'Gurgaon Sec - 10'!K18+'Paschim Vihar'!K18+Kalkaji!K18+CP!K18+Rohini!K18+'Model Town'!K18+'Pacific Mall'!K18 -> 3759509.2 | M20: ='Noida Sec - 18'!L18+'Noida Sec -143'!L18+DLF!L18+'Faridabad Sec15'!L18+'Gurgaon Sec-15'!L18+'Gurgaon Sec - 10'!L18+'Paschim Vihar'!L18+Kalkaji!L18+CP!L18+Rohini!L18+'Model Town'!L18+'Pacific Mall'!L18 -> 3759898.3 | N20: ='Noida Sec - 18'!M18+'Noida Sec -143'!M18+DLF!M18+'Faridabad Sec15'!M18+'Gurgaon Sec-15'!M18+'Gurgaon Sec - 10'!M18+'Paschim Vihar'!M18+Kalkaji!M18+CP!M18+Rohini!M18+'Model Town'!M18+'Pacific Mall'!M18+'Shalimar Bagh'!M18 -> 3821494.5 | O20: =sum(C20:N20) -> 45106697 | P20: =O20/$O$15 -> 0.23277685 | Q20: =AVERAGE(C20:N20)/11 -> 341717.4
A21: Insurance | B21: Accounts | C21: ='Noida Sec - 18'!B19+'Noida Sec -143'!B19+'Faridabad Sec15'!B19+DLF!B19+'Gurgaon Sec-15'!B19+'Paschim Vihar'!B19+Kalkaji!B19+CP!B19+Rohini!B19+'Model Town'!B19+'Pacific Mall'!B19 -> 0 | D21: ='Noida Sec - 18'!C19+'Noida Sec -143'!C19+'Faridabad Sec15'!C19+DLF!C19+'Gurgaon Sec-15'!C19+'Paschim Vihar'!C19+Kalkaji!C19+CP!C19+Rohini!C19+'Model Town'!C19+'Pacific Mall'!C19 -> 12761.936 | E21: ='Noida Sec - 18'!D19+'Noida Sec -143'!D19+'Faridabad Sec15'!D19+DLF!D19+'Gurgaon Sec-15'!D19+'Paschim Vihar'!D19+Kalkaji!D19+CP!D19+Rohini!D19+'Model Town'!D19+'Pacific Mall'!D19 -> 12761.936 | F21: ='Noida Sec - 18'!E19+'Noida Sec -143'!E19+'Faridabad Sec15'!E19+DLF!E19+'Gurgaon Sec-15'!E19+'Paschim Vihar'!E19+Kalkaji!E19+CP!E19+Rohini!E19+'Model Town'!E19+'Pacific Mall'!E19 -> 12761.936 | G21: ='Noida Sec - 18'!F19+'Noida Sec -143'!F19+'Faridabad Sec15'!F19+DLF!F19+'Gurgaon Sec-15'!F19+'Paschim Vihar'!F19+Kalkaji!F19+CP!F19+Rohini!F19+'Model Town'!F19+'Pacific Mall'!F19 -> 12761.936 | H21: ='Noida Sec - 18'!G19+'Noida Sec -143'!G19+'Faridabad Sec15'!G19+DLF!G19+'Gurgaon Sec-15'!G19+'Paschim Vihar'!G19+Kalkaji!G19+CP!G19+Rohini!G19+'Model Town'!G19+'Pacific Mall'!G19 -> 12761.936 | I21: ='Noida Sec - 18'!H19+'Noida Sec -143'!H19+'Faridabad Sec15'!H19+DLF!H19+'Gurgaon Sec-15'!H19+'Paschim Vihar'!H19+Kalkaji!H19+CP!H19+Rohini!H19+'Model Town'!H19+'Pacific Mall'!H19 -> 12761.936 | J21: ='Noida Sec - 18'!I19+'Noida Sec -143'!I19+'Faridabad Sec15'!I19+DLF!I19+'Gurgaon Sec-15'!I19+'Paschim Vihar'!I19+Kalkaji!I19+CP!I19+Rohini!I19+'Model Town'!I19+'Pacific Mall'!I19 -> 12761.936 | K21: ='Noida Sec - 18'!J19+'Noida Sec -143'!J19+'Faridabad Sec15'!J19+DLF!J19+'Gurgaon Sec-15'!J19+'Paschim Vihar'!J19+Kalkaji!J19+CP!J19+Rohini!J19+'Model Town'!J19+'Pacific Mall'!J19+'Gurgaon Sec - 10'!J19 -> 14416.769 | L21: ='Noida Sec - 18'!K19+'Noida Sec -143'!K19+DLF!K19+'Faridabad Sec15'!K19+'Gurgaon Sec-15'!K19+'Gurgaon Sec - 10'!K19+'Paschim Vihar'!K19+Kalkaji!K19+CP!K19+Rohini!K19+'Model Town'!K19+'Pacific Mall'!K19 -> 14416.769 | M21: ='Noida Sec - 18'!L19+'Noida Sec -143'!L19+DLF!L19+'Faridabad Sec15'!L19+'Gurgaon Sec-15'!L19+'Gurgaon Sec - 10'!L19+'Paschim Vihar'!L19+Kalkaji!L19+CP!L19+Rohini!L19+'Model Town'!L19+'Pacific Mall'!L19 -> 14416.769 | N21: ='Noida Sec - 18'!M19+'Noida Sec -143'!M19+DLF!M19+'Faridabad Sec15'!M19+'Gurgaon Sec-15'!M19+'Gurgaon Sec - 10'!M19+'Paschim Vihar'!M19+Kalkaji!M19+CP!M19+Rohini!M19+'Model Town'!M19+'Pacific Mall'!M19 -> 14416.769 | O21: =sum(C21:N21) -> 147000.63 | P21: =O21/$O$15 -> 0.00075860893 | Q21: =AVERAGE(C21:N21)/11 -> 1113.6411
A22: Software | B22: Operation | C22: ='Noida Sec - 18'!B20+'Noida Sec -143'!B20+'Faridabad Sec15'!B20+DLF!B20+'Gurgaon Sec-15'!B20+'Paschim Vihar'!B20+Kalkaji!B20+CP!B20+Rohini!B20+'Model Town'!B20+'Pacific Mall'!B20 -> 83255.583 | D22: ='Noida Sec - 18'!C20+'Noida Sec -143'!C20+'Faridabad Sec15'!C20+DLF!C20+'Gurgaon Sec-15'!C20+'Paschim Vihar'!C20+Kalkaji!C20+CP!C20+Rohini!C20+'Model Town'!C20+'Pacific Mall'!C20 -> 81166 | E22: ='Noida Sec - 18'!D20+'Noida Sec -143'!D20+'Faridabad Sec15'!D20+DLF!D20+'Gurgaon Sec-15'!D20+'Paschim Vihar'!D20+Kalkaji!D20+CP!D20+Rohini!D20+'Model Town'!D20+'Pacific Mall'!D20 -> 81166 | F22: ='Noida Sec - 18'!E20+'Noida Sec -143'!E20+'Faridabad Sec15'!E20+DLF!E20+'Gurgaon Sec-15'!E20+'Paschim Vihar'!E20+Kalkaji!E20+CP!E20+Rohini!E20+'Model Town'!E20+'Pacific Mall'!E20 -> 81166 | G22: ='Noida Sec - 18'!F20+'Noida Sec -143'!F20+'Faridabad Sec15'!F20+DLF!F20+'Gurgaon Sec-15'!F20+'Paschim Vihar'!F20+Kalkaji!F20+CP!F20+Rohini!F20+'Model Town'!F20+'Pacific Mall'!F20 -> 81166 | H22: ='Noida Sec - 18'!G20+'Noida Sec -143'!G20+'Faridabad Sec15'!G20+DLF!G20+'Gurgaon Sec-15'!G20+'Paschim Vihar'!G20+Kalkaji!G20+CP!G20+Rohini!G20+'Model Town'!G20+'Pacific Mall'!G20 -> 79076.417 | I22: ='Noida Sec - 18'!H20+'Noida Sec -143'!H20+'Faridabad Sec15'!H20+DLF!H20+'Gurgaon Sec-15'!H20+'Paschim Vihar'!H20+Kalkaji!H20+CP!H20+Rohini!H20+'Model Town'!H20+'Pacific Mall'!H20 -> 74927.25 | J22: ='Noida Sec - 18'!I20+'Noida Sec -143'!I20+'Faridabad Sec15'!I20+DLF!I20+'Gurgaon Sec-15'!I20+'Paschim Vihar'!I20+Kalkaji!I20+CP!I20+Rohini!I20+'Model Town'!I20+'Pacific Mall'!I20 -> 74927.25 | K22: ='Noida Sec - 18'!J20+'Noida Sec -143'!J20+'Faridabad Sec15'!J20+DLF!J20+'Gurgaon Sec-15'!J20+'Paschim Vihar'!J20+Kalkaji!J20+CP!J20+Rohini!J20+'Model Town'!J20+'Pacific Mall'!J20+'Gurgaon Sec - 10'!J20 -> 82784.083 | L22: ='Noida Sec - 18'!K20+'Noida Sec -143'!K20+DLF!K20+'Faridabad Sec15'!K20+'Gurgaon Sec-15'!K20+'Gurgaon Sec - 10'!K20+'Paschim Vihar'!K20+Kalkaji!K20+CP!K20+Rohini!K20+'Model Town'!K20+'Pacific Mall'!K20 -> 82784.083 | M22: ='Noida Sec - 18'!L20+'Noida Sec -143'!L20+DLF!L20+'Faridabad Sec15'!L20+'Gurgaon Sec-15'!L20+'Gurgaon Sec - 10'!L20+'Paschim Vihar'!L20+Kalkaji!L20+CP!L20+Rohini!L20+'Model Town'!L20+'Pacific Mall'!L20 -> 80947.583 | N22: ='Noida Sec - 18'!M20+'Noida Sec -143'!M20+DLF!M20+'Faridabad Sec15'!M20+'Gurgaon Sec-15'!M20+'Gurgaon Sec - 10'!M20+'Paschim Vihar'!M20+Kalkaji!M20+CP!M20+Rohini!M20+'Model Town'!M20+'Pacific Mall'!M20 -> 80947.583 | O22: =sum(C22:N22) -> 964313.83 | P22: =O22/$O$15 -> 0.0049764215 | Q22: =AVERAGE(C22:N22)/11 -> 7305.4078
A23: Staff Salary | B23: HR | C23: ='Noida Sec - 18'!B21+'Noida Sec -143'!B21+'Faridabad Sec15'!B21+DLF!B21+'Gurgaon Sec-15'!B21+'Paschim Vihar'!B21+Kalkaji!B21+CP!B21+Rohini!B21+'Model Town'!B21+'Pacific Mall'!B21 -> 3513263.6 | D23: ='Noida Sec - 18'!C21+'Noida Sec -143'!C21+'Faridabad Sec15'!C21+DLF!C21+'Gurgaon Sec-15'!C21+'Paschim Vihar'!C21+Kalkaji!C21+CP!C21+Rohini!C21+'Model Town'!C21+'Pacific Mall'!C21 -> 3508561.2 | E23: ='Noida Sec - 18'!D21+'Noida Sec -143'!D21+'Faridabad Sec15'!D21+DLF!D21+'Gurgaon Sec-15'!D21+'Paschim Vihar'!D21+Kalkaji!D21+CP!D21+Rohini!D21+'Model Town'!D21+'Pacific Mall'!D21 -> 3615510.4 | F23: ='Noida Sec - 18'!E21+'Noida Sec -143'!E21+'Faridabad Sec15'!E21+DLF!E21+'Gurgaon Sec-15'!E21+'Paschim Vihar'!E21+Kalkaji!E21+CP!E21+Rohini!E21+'Model Town'!E21+'Pacific Mall'!E21 -> 3598622.3 | G23: ='Noida Sec - 18'!F21+'Noida Sec -143'!F21+'Faridabad Sec15'!F21+DLF!F21+'Gurgaon Sec-15'!F21+'Paschim Vihar'!F21+Kalkaji!F21+CP!F21+Rohini!F21+'Model Town'!F21+'Pacific Mall'!F21 -> 3604374.4 | H23: ='Noida Sec - 18'!G21+'Noida Sec -143'!G21+'Faridabad Sec15'!G21+DLF!G21+'Gurgaon Sec-15'!G21+'Paschim Vihar'!G21+Kalkaji!G21+CP!G21+Rohini!G21+'Model Town'!G21+'Pacific Mall'!G21 -> 3630726.1 | I23: ='Noida Sec - 18'!H21+'Noida Sec -143'!H21+'Faridabad Sec15'!H21+DLF!H21+'Gurgaon Sec-15'!H21+'Paschim Vihar'!H21+Kalkaji!H21+CP!H21+Rohini!H21+'Model Town'!H21+'Pacific Mall'!H21 -> 3557967.5 | J23: ='Noida Sec - 18'!I21+'Noida Sec -143'!I21+'Faridabad Sec15'!I21+DLF!I21+'Gurgaon Sec-15'!I21+'Paschim Vihar'!I21+Kalkaji!I21+CP!I21+Rohini!I21+'Model Town'!I21+'Pacific Mall'!I21 -> 3555118 | K23: ='Noida Sec - 18'!J21+'Noida Sec -143'!J21+'Faridabad Sec15'!J21+DLF!J21+'Gurgaon Sec-15'!J21+'Paschim Vihar'!J21+Kalkaji!J21+CP!J21+Rohini!J21+'Model Town'!J21+'Pacific Mall'!J21+'Gurgaon Sec - 10'!J21 -> 3714348.8 | L23: ='Noida Sec - 18'!K21+'Noida Sec -143'!K21+DLF!K21+'Faridabad Sec15'!K21+'Gurgaon Sec-15'!K21+'Gurgaon Sec - 10'!K21+'Paschim Vihar'!K21+Kalkaji!K21+CP!K21+Rohini!K21+'Model Town'!K21+'Pacific Mall'!K21 -> 3886180.8 | M23: ='Noida Sec - 18'!L21+'Noida Sec -143'!L21+DLF!L21+'Faridabad Sec15'!L21+'Gurgaon Sec-15'!L21+'Gurgaon Sec - 10'!L21+'Paschim Vihar'!L21+Kalkaji!L21+CP!L21+Rohini!L21+'Model Town'!L21+'Pacific Mall'!L21 -> 3807968.8 | N23: ='Noida Sec - 18'!M21+'Noida Sec -143'!M21+DLF!M21+'Faridabad Sec15'!M21+'Gurgaon Sec-15'!M21+'Gurgaon Sec - 10'!M21+'Paschim Vihar'!M21+Kalkaji!M21+CP!M21+Rohini!M21+'Model Town'!M21+'Pacific Mall'!M21+'Shalimar Bagh'!M21 -> 3840778.6 | O23: =sum(C23:N23) -> 43833420 | P23: =O23/$O$15 -> 0.226206 | Q23: =AVERAGE(C23:N23)/11 -> 332071.37
A24: AMC | B24: Operation | C24: ='Noida Sec - 18'!B22+'Noida Sec -143'!B22+'Faridabad Sec15'!B22+DLF!B22+'Gurgaon Sec-15'!B22+'Paschim Vihar'!B22+Kalkaji!B22+CP!B22+Rohini!B22+'Model Town'!B22+'Pacific Mall'!B22 -> 97907.75 | D24: ='Noida Sec - 18'!C22+'Noida Sec -143'!C22+'Faridabad Sec15'!C22+DLF!C22+'Gurgaon Sec-15'!C22+'Paschim Vihar'!C22+Kalkaji!C22+CP!C22+Rohini!C22+'Model Town'!C22+'Pacific Mall'!C22 -> 98143.75 | E24: ='Noida Sec - 18'!D22+'Noida Sec -143'!D22+'Faridabad Sec15'!D22+DLF!D22+'Gurgaon Sec-15'!D22+'Paschim Vihar'!D22+Kalkaji!D22+CP!D22+Rohini!D22+'Model Town'!D22+'Pacific Mall'!D22 -> 99313.917 | F24: ='Noida Sec - 18'!E22+'Noida Sec -143'!E22+'Faridabad Sec15'!E22+DLF!E22+'Gurgaon Sec-15'!E22+'Paschim Vihar'!E22+Kalkaji!E22+CP!E22+Rohini!E22+'Model Town'!E22+'Pacific Mall'!E22 -> 99549.917 | G24: ='Noida Sec - 18'!F22+'Noida Sec -143'!F22+'Faridabad Sec15'!F22+DLF!F22+'Gurgaon Sec-15'!F22+'Paschim Vihar'!F22+Kalkaji!F22+CP!F22+Rohini!F22+'Model Town'!F22+'Pacific Mall'!F22 -> 102499.92 | H24: ='Noida Sec - 18'!G22+'Noida Sec -143'!G22+'Faridabad Sec15'!G22+DLF!G22+'Gurgaon Sec-15'!G22+'Paschim Vihar'!G22+Kalkaji!G22+CP!G22+Rohini!G22+'Model Town'!G22+'Pacific Mall'!G22 -> 102499.92 | I24: ='Noida Sec - 18'!H22+'Noida Sec -143'!H22+'Faridabad Sec15'!H22+DLF!H22+'Gurgaon Sec-15'!H22+'Paschim Vihar'!H22+Kalkaji!H22+CP!H22+Rohini!H22+'Model Town'!H22+'Pacific Mall'!H22 -> 105449.5 | J24: ='Noida Sec - 18'!I22+'Noida Sec -143'!I22+'Faridabad Sec15'!I22+DLF!I22+'Gurgaon Sec-15'!I22+'Paschim Vihar'!I22+Kalkaji!I22+CP!I22+Rohini!I22+'Model Town'!I22+'Pacific Mall'!I22 -> 100377.5 | K24: ='Noida Sec - 18'!J22+'Noida Sec -143'!J22+'Faridabad Sec15'!J22+DLF!J22+'Gurgaon Sec-15'!J22+'Paschim Vihar'!J22+Kalkaji!J22+CP!J22+Rohini!J22+'Model Town'!J22+'Pacific Mall'!J22+'Gurgaon Sec - 10'!J22 -> 100257.5 | L24: ='Noida Sec - 18'!K22+'Noida Sec -143'!K22+DLF!K22+'Faridabad Sec15'!K22+'Gurgaon Sec-15'!K22+'Gurgaon Sec - 10'!K22+'Paschim Vihar'!K22+Kalkaji!K22+CP!K22+Rohini!K22+'Model Town'!K22+'Pacific Mall'!K22 -> 104977.5 | M24: ='Noida Sec - 18'!L22+'Noida Sec -143'!L22+DLF!L22+'Faridabad Sec15'!L22+'Gurgaon Sec-15'!L22+'Gurgaon Sec - 10'!L22+'Paschim Vihar'!L22+Kalkaji!L22+CP!L22+Rohini!L22+'Model Town'!L22+'Pacific Mall'!L22 -> 104977.5 | N24: ='Noida Sec - 18'!M22+'Noida Sec -143'!M22+DLF!M22+'Faridabad Sec15'!M22+'Gurgaon Sec-15'!M22+'Gurgaon Sec - 10'!M22+'Paschim Vihar'!M22+Kalkaji!M22+CP!M22+Rohini!M22+'Model Town'!M22+'Pacific Mall'!M22 -> 104977.5 | O24: =sum(C24:N24) -> 1220932.2 | P24: =O24/$O$15 -> 0.0063007217 | Q24: =AVERAGE(C24:N24)/11 -> 9249.4861
A25: Subscription | B25: Operation | C25: ='Noida Sec - 18'!B23+'Noida Sec -143'!B23+'Faridabad Sec15'!B23+DLF!B23+'Gurgaon Sec-15'!B23+'Paschim Vihar'!B23+Kalkaji!B23+CP!B23+Rohini!B23+'Model Town'!B23+'Pacific Mall'!B23 -> 7978.25 | D25: ='Noida Sec - 18'!C23+'Noida Sec -143'!C23+'Faridabad Sec15'!C23+DLF!C23+'Gurgaon Sec-15'!C23+'Paschim Vihar'!C23+Kalkaji!C23+CP!C23+Rohini!C23+'Model Town'!C23+'Pacific Mall'!C23 -> 7978.25 | E25: ='Noida Sec - 18'!D23+'Noida Sec -143'!D23+'Faridabad Sec15'!D23+DLF!D23+'Gurgaon Sec-15'!D23+'Paschim Vihar'!D23+Kalkaji!D23+CP!D23+Rohini!D23+'Model Town'!D23+'Pacific Mall'!D23 -> 7978.25 | F25: ='Noida Sec - 18'!E23+'Noida Sec -143'!E23+'Faridabad Sec15'!E23+DLF!E23+'Gurgaon Sec-15'!E23+'Paschim Vihar'!E23+Kalkaji!E23+CP!E23+Rohini!E23+'Model Town'!E23+'Pacific Mall'!E23 -> 7978.25 | G25: ='Noida Sec - 18'!F23+'Noida Sec -143'!F23+'Faridabad Sec15'!F23+DLF!F23+'Gurgaon Sec-15'!F23+'Paschim Vihar'!F23+Kalkaji!F23+CP!F23+Rohini!F23+'Model Town'!F23+'Pacific Mall'!F23 -> 7978.25 | H25: ='Noida Sec - 18'!G23+'Noida Sec -143'!G23+'Faridabad Sec15'!G23+DLF!G23+'Gurgaon Sec-15'!G23+'Paschim Vihar'!G23+Kalkaji!G23+CP!G23+Rohini!G23+'Model Town'!G23+'Pacific Mall'!G23 -> 7978.25 | I25: ='Noida Sec - 18'!H23+'Noida Sec -143'!H23+'Faridabad Sec15'!H23+DLF!H23+'Gurgaon Sec-15'!H23+'Paschim Vihar'!H23+Kalkaji!H23+CP!H23+Rohini!H23+'Model Town'!H23+'Pacific Mall'!H23 -> 9394.25 | J25: ='Noida Sec - 18'!I23+'Noida Sec -143'!I23+'Faridabad Sec15'!I23+DLF!I23+'Gurgaon Sec-15'!I23+'Paschim Vihar'!I23+Kalkaji!I23+CP!I23+Rohini!I23+'Model Town'!I23+'Pacific Mall'!I23 -> 9394.25 | K25: ='Noida Sec - 18'!J23+'Noida Sec -143'!J23+'Faridabad Sec15'!J23+DLF!J23+'Gurgaon Sec-15'!J23+'Paschim Vihar'!J23+Kalkaji!J23+CP!J23+Rohini!J23+'Model Town'!J23+'Pacific Mall'!J23+'Gurgaon Sec - 10'!J23 -> 9394.25 | L25: ='Noida Sec - 18'!K23+'Noida Sec -143'!K23+DLF!K23+'Faridabad Sec15'!K23+'Gurgaon Sec-15'!K23+'Gurgaon Sec - 10'!K23+'Paschim Vihar'!K23+Kalkaji!K23+CP!K23+Rohini!K23+'Model Town'!K23+'Pacific Mall'!K23 -> 14822.25 | M25: ='Noida Sec - 18'!L23+'Noida Sec -143'!L23+DLF!L23+'Faridabad Sec15'!L23+'Gurgaon Sec-15'!L23+'Gurgaon Sec - 10'!L23+'Paschim Vihar'!L23+Kalkaji!L23+CP!L23+Rohini!L23+'Model Town'!L23+'Pacific Mall'!L23 -> 14822.25 | N25: ='Noida Sec - 18'!M23+'Noida Sec -143'!M23+DLF!M23+'Faridabad Sec15'!M23+'Gurgaon Sec-15'!M23+'Gurgaon Sec - 10'!M23+'Paschim Vihar'!M23+Kalkaji!M23+CP!M23+Rohini!M23+'Model Town'!M23+'Pacific Mall'!M23 -> 14822.25 | O25: =sum(C25:N25) -> 120519 | P25: =O25/$O$15 -> 0.0006219483 | Q25: =AVERAGE(C25:N25)/11 -> 913.02273
A26: Repairs & Maintenance | B26: Operation | C26: ='Noida Sec - 18'!B24+'Noida Sec -143'!B24+'Faridabad Sec15'!B24+DLF!B24+'Gurgaon Sec-15'!B24+'Paschim Vihar'!B24+Kalkaji!B24+CP!B24+Rohini!B24+'Model Town'!B24+'Pacific Mall'!B24 -> 31978 | D26: ='Noida Sec - 18'!C24+'Noida Sec -143'!C24+'Faridabad Sec15'!C24+DLF!C24+'Gurgaon Sec-15'!C24+'Paschim Vihar'!C24+Kalkaji!C24+CP!C24+Rohini!C24+'Model Town'!C24+'Pacific Mall'!C24 -> 17647 | E26: ='Noida Sec - 18'!D24+'Noida Sec -143'!D24+'Faridabad Sec15'!D24+DLF!D24+'Gurgaon Sec-15'!D24+'Paschim Vihar'!D24+Kalkaji!D24+CP!D24+Rohini!D24+'Model Town'!D24+'Pacific Mall'!D24 -> 39307 | F26: ='Noida Sec - 18'!E24+'Noida Sec -143'!E24+'Faridabad Sec15'!E24+DLF!E24+'Gurgaon Sec-15'!E24+'Paschim Vihar'!E24+Kalkaji!E24+CP!E24+Rohini!E24+'Model Town'!E24+'Pacific Mall'!E24 -> 34351 | G26: ='Noida Sec - 18'!F24+'Noida Sec -143'!F24+'Faridabad Sec15'!F24+DLF!F24+'Gurgaon Sec-15'!F24+'Paschim Vihar'!F24+Kalkaji!F24+CP!F24+Rohini!F24+'Model Town'!F24+'Pacific Mall'!F24 -> 143401 | H26: ='Noida Sec - 18'!G24+'Noida Sec -143'!G24+'Faridabad Sec15'!G24+DLF!G24+'Gurgaon Sec-15'!G24+'Paschim Vihar'!G24+Kalkaji!G24+CP!G24+Rohini!G24+'Model Town'!G24+'Pacific Mall'!G24 -> 86511 | I26: ='Noida Sec - 18'!H24+'Noida Sec -143'!H24+'Faridabad Sec15'!H24+DLF!H24+'Gurgaon Sec-15'!H24+'Paschim Vihar'!H24+Kalkaji!H24+CP!H24+Rohini!H24+'Model Town'!H24+'Pacific Mall'!H24 -> 61040 | J26: ='Noida Sec - 18'!I24+'Noida Sec -143'!I24+'Faridabad Sec15'!I24+DLF!I24+'Gurgaon Sec-15'!I24+'Paschim Vihar'!I24+Kalkaji!I24+CP!I24+Rohini!I24+'Model Town'!I24+'Pacific Mall'!I24 -> 136540 | K26: ='Noida Sec - 18'!J24+'Noida Sec -143'!J24+'Faridabad Sec15'!J24+DLF!J24+'Gurgaon Sec-15'!J24+'Paschim Vihar'!J24+Kalkaji!J24+CP!J24+Rohini!J24+'Model Town'!J24+'Pacific Mall'!J24 -> 27917 | L26: ='Noida Sec - 18'!K24+'Noida Sec -143'!K24+DLF!K24+'Faridabad Sec15'!K24+'Gurgaon Sec-15'!K24+'Gurgaon Sec - 10'!K24+'Paschim Vihar'!K24+Kalkaji!K24+CP!K24+Rohini!K24+'Model Town'!K24+'Pacific Mall'!K24 -> 43556 | M26: ='Noida Sec - 18'!L24+'Noida Sec -143'!L24+DLF!L24+'Faridabad Sec15'!L24+'Gurgaon Sec-15'!L24+'Gurgaon Sec - 10'!L24+'Paschim Vihar'!L24+Kalkaji!L24+CP!L24+Rohini!L24+'Model Town'!L24+'Pacific Mall'!L24 -> 200241 | N26: ='Noida Sec - 18'!M24+'Noida Sec -143'!M24+DLF!M24+'Faridabad Sec15'!M24+'Gurgaon Sec-15'!M24+'Gurgaon Sec - 10'!M24+'Paschim Vihar'!M24+Kalkaji!M24+CP!M24+Rohini!M24+'Model Town'!M24+'Pacific Mall'!M24 -> 64438.82 | O26: =sum(C26:N26) -> 886927.82 | P26: =O26/$O$15 -> 0.0045770646 | Q26: =AVERAGE(C26:N26)/11 -> 6719.1502
A27: Miscellaneous Expenses | B27: Accounts | C27: ='Noida Sec - 18'!B25+'Noida Sec -143'!B25+'Faridabad Sec15'!B25+DLF!B25+'Gurgaon Sec-15'!B25+'Paschim Vihar'!B25+Kalkaji!B25+CP!B25+Rohini!B25+'Model Town'!B25+'Pacific Mall'!B25 -> 94756.87 | D27: ='Noida Sec - 18'!C25+'Noida Sec -143'!C25+'Faridabad Sec15'!C25+DLF!C25+'Gurgaon Sec-15'!C25+'Paschim Vihar'!C25+Kalkaji!C25+CP!C25+Rohini!C25+'Model Town'!C25+'Pacific Mall'!C25 -> 110055.62 | E27: ='Noida Sec - 18'!D25+'Noida Sec -143'!D25+'Faridabad Sec15'!D25+DLF!D25+'Gurgaon Sec-15'!D25+'Paschim Vihar'!D25+Kalkaji!D25+CP!D25+Rohini!D25+'Model Town'!D25+'Pacific Mall'!D25 -> 124906.5 | F27: ='Noida Sec - 18'!E25+'Noida Sec -143'!E25+'Faridabad Sec15'!E25+DLF!E25+'Gurgaon Sec-15'!E25+'Paschim Vihar'!E25+Kalkaji!E25+CP!E25+Rohini!E25+'Model Town'!E25+'Pacific Mall'!E25 -> 80255.397 | G27: ='Noida Sec - 18'!F25+'Noida Sec -143'!F25+'Faridabad Sec15'!F25+DLF!F25+'Gurgaon Sec-15'!F25+'Paschim Vihar'!F25+Kalkaji!F25+CP!F25+Rohini!F25+'Model Town'!F25+'Pacific Mall'!F25 -> 284362.95 | H27: ='Noida Sec - 18'!G25+'Noida Sec -143'!G25+'Faridabad Sec15'!G25+DLF!G25+'Gurgaon Sec-15'!G25+'Paschim Vihar'!G25+Kalkaji!G25+CP!G25+Rohini!G25+'Model Town'!G25+'Pacific Mall'!G25 -> 187513.94 | I27: ='Noida Sec - 18'!H25+'Noida Sec -143'!H25+'Faridabad Sec15'!H25+DLF!H25+'Gurgaon Sec-15'!H25+'Paschim Vihar'!H25+Kalkaji!H25+CP!H25+Rohini!H25+'Model Town'!H25+'Pacific Mall'!H25 -> 147122.04 | J27: ='Noida Sec - 18'!I25+'Noida Sec -143'!I25+'Faridabad Sec15'!I25+DLF!I25+'Gurgaon Sec-15'!I25+'Paschim Vihar'!I25+Kalkaji!I25+CP!I25+Rohini!I25+'Model Town'!I25+'Pacific Mall'!I25 -> 181422.14 | K27: ='Noida Sec - 18'!J25+'Noida Sec -143'!J25+'Faridabad Sec15'!J25+DLF!J25+'Gurgaon Sec-15'!J25+'Paschim Vihar'!J25+Kalkaji!J25+CP!J25+Rohini!J25+'Model Town'!J25+'Pacific Mall'!J25 -> 139650.94 | L27: ='Noida Sec - 18'!K25+'Noida Sec -143'!K25+DLF!K25+'Faridabad Sec15'!K25+'Gurgaon Sec-15'!K25+'Gurgaon Sec - 10'!K25+'Paschim Vihar'!K25+Kalkaji!K25+CP!K25+Rohini!K25+'Model Town'!K25+'Pacific Mall'!K25 -> 153833.11 | M27: ='Noida Sec - 18'!L25+'Noida Sec -143'!L25+DLF!L25+'Faridabad Sec15'!L25+'Gurgaon Sec-15'!L25+'Gurgaon Sec - 10'!L25+'Paschim Vihar'!L25+Kalkaji!L25+CP!L25+Rohini!L25+'Model Town'!L25+'Pacific Mall'!L25 -> 294015.03 | N27: ='Noida Sec - 18'!M25+'Noida Sec -143'!M25+DLF!M25+'Faridabad Sec15'!M25+'Gurgaon Sec-15'!M25+'Gurgaon Sec - 10'!M25+'Paschim Vihar'!M25+Kalkaji!M25+CP!M25+Rohini!M25+'Model Town'!M25+'Pacific Mall'!M25 -> 187135.1 | O27: =sum(C27:N27) -> 1985029.6 | P27: =O27/$O$15 -> 0.01024391 | Q27: =AVERAGE(C27:N27)/11 -> 15038.103
A28: CAM | B28: Accounts | C28: ='Noida Sec - 18'!B26+'Noida Sec -143'!B26+'Faridabad Sec15'!B26+DLF!B26+'Gurgaon Sec-15'!B26+'Paschim Vihar'!B26+Kalkaji!B26+CP!B26+Rohini!B26+'Model Town'!B26+'Pacific Mall'!B26 -> 212132.5 | D28: ='Noida Sec - 18'!C26+'Noida Sec -143'!C26+'Faridabad Sec15'!C26+DLF!C26+'Gurgaon Sec-15'!C26+'Paschim Vihar'!C26+Kalkaji!C26+CP!C26+Rohini!C26+'Model Town'!C26+'Pacific Mall'!C26 -> 216928.5 | E28: ='Noida Sec - 18'!D26+'Noida Sec -143'!D26+'Faridabad Sec15'!D26+DLF!D26+'Gurgaon Sec-15'!D26+'Paschim Vihar'!D26+Kalkaji!D26+CP!D26+Rohini!D26+'Model Town'!D26+'Pacific Mall'!D26 -> 219902.5 | F28: ='Noida Sec - 18'!E26+'Noida Sec -143'!E26+'Faridabad Sec15'!E26+DLF!E26+'Gurgaon Sec-15'!E26+'Paschim Vihar'!E26+Kalkaji!E26+CP!E26+Rohini!E26+'Model Town'!E26+'Pacific Mall'!E26 -> 219042.5 | G28: ='Noida Sec - 18'!F26+'Noida Sec -143'!F26+'Faridabad Sec15'!F26+DLF!F26+'Gurgaon Sec-15'!F26+'Paschim Vihar'!F26+Kalkaji!F26+CP!F26+Rohini!F26+'Model Town'!F26+'Pacific Mall'!F26 -> 221288.5 | H28: ='Noida Sec - 18'!G26+'Noida Sec -143'!G26+'Faridabad Sec15'!G26+DLF!G26+'Gurgaon Sec-15'!G26+'Paschim Vihar'!G26+Kalkaji!G26+CP!G26+Rohini!G26+'Model Town'!G26+'Pacific Mall'!G26 -> 221288.5 | I28: ='Noida Sec - 18'!H26+'Noida Sec -143'!H26+'Faridabad Sec15'!H26+DLF!H26+'Gurgaon Sec-15'!H26+'Paschim Vihar'!H26+Kalkaji!H26+CP!H26+Rohini!H26+'Model Town'!H26+'Pacific Mall'!H26 -> 221288.5 | J28: ='Noida Sec - 18'!I26+'Noida Sec -143'!I26+'Faridabad Sec15'!I26+DLF!I26+'Gurgaon Sec-15'!I26+'Paschim Vihar'!I26+Kalkaji!I26+CP!I26+Rohini!I26+'Model Town'!I26+'Pacific Mall'!I26 -> 214880.5 | K28: ='Noida Sec - 18'!J26+'Noida Sec -143'!J26+'Faridabad Sec15'!J26+DLF!J26+'Gurgaon Sec-15'!J26+'Paschim Vihar'!J26+Kalkaji!J26+CP!J26+Rohini!J26+'Model Town'!J26+'Pacific Mall'!J26 -> 212962.5 | L28: ='Noida Sec - 18'!K26+'Noida Sec -143'!K26+DLF!K26+'Faridabad Sec15'!K26+'Gurgaon Sec-15'!K26+'Gurgaon Sec - 10'!K26+'Paschim Vihar'!K26+Kalkaji!K26+CP!K26+Rohini!K26+'Model Town'!K26+'Pacific Mall'!K26 -> 212170.5 | M28: ='Noida Sec - 18'!L26+'Noida Sec -143'!L26+DLF!L26+'Faridabad Sec15'!L26+'Gurgaon Sec-15'!L26+'Gurgaon Sec - 10'!L26+'Paschim Vihar'!L26+Kalkaji!L26+CP!L26+Rohini!L26+'Model Town'!L26+'Pacific Mall'!L26 -> 213194.5 | N28: ='Noida Sec - 18'!M26+'Noida Sec -143'!M26+DLF!M26+'Faridabad Sec15'!M26+'Gurgaon Sec-15'!M26+'Gurgaon Sec - 10'!M26+'Paschim Vihar'!M26+Kalkaji!M26+CP!M26+Rohini!M26+'Model Town'!M26+'Pacific Mall'!M26+'Shalimar Bagh'!M26 -> 221907.39 | O28: =sum(C28:N28) -> 2606986.9 | P28: =O28/$O$15 -> 0.013453572 | Q28: =AVERAGE(C28:N28)/11 -> 19749.901
A29: Ads Account | B29: Accounts | C29: ='Ads Account'!B6 -> 773726.67 | D29: ='Ads Account'!C6 -> 632593.56 | E29: ='Ads Account'!D6 -> 574335.34 | F29: ='Ads Account'!E6 -> 547564.9 | G29: ='Ads Account'!F6 -> 668555.48 | H29: ='Ads Account'!G6 -> 421036.56 | I29: ='Ads Account'!H6 -> 488867.74 | J29: ='Ads Account'!I6 -> 497839.81 | ... N29: ='Ads Account'!M6 -> 711696.38 | O29: =sum(C29:N29) -> 7296855.5 | P29: =O29/$O$15 -> 0.037656028 | Q29: =AVERAGE(C29:N29)/11 -> 55279.208
A30: HO+CK Cost | B30: Accounts | C30: ='Noida Sec - 18'!B27+'Noida Sec -143'!B27+'Faridabad Sec15'!B27+DLF!B27+'Gurgaon Sec-15'!B27+'Paschim Vihar'!B27+Kalkaji!B27+CP!B27+Rohini!B27+'Model Town'!B27+'Pacific Mall'!B27 -> 2677264.4 | D30: ='Noida Sec - 18'!C27+'Noida Sec -143'!C27+'Faridabad Sec15'!C27+DLF!C27+'Gurgaon Sec-15'!C27+'Paschim Vihar'!C27+Kalkaji!C27+CP!C27+Rohini!C27+'Model Town'!C27+'Pacific Mall'!C27 -> 2785745.2 | E30: ='Noida Sec - 18'!D27+'Noida Sec -143'!D27+'Faridabad Sec15'!D27+DLF!D27+'Gurgaon Sec-15'!D27+'Paschim Vihar'!D27+Kalkaji!D27+CP!D27+Rohini!D27+'Model Town'!D27+'Pacific Mall'!D27 -> 2709914.1 | F30: ='Noida Sec - 18'!E27+'Noida Sec -143'!E27+'Faridabad Sec15'!E27+DLF!E27+'Gurgaon Sec-15'!E27+'Paschim Vihar'!E27+Kalkaji!E27+CP!E27+Rohini!E27+'Model Town'!E27+'Pacific Mall'!E27 -> 2900178.6 | G30: ='Noida Sec - 18'!F27+'Noida Sec -143'!F27+'Faridabad Sec15'!F27+DLF!F27+'Gurgaon Sec-15'!F27+'Paschim Vihar'!F27+Kalkaji!F27+CP!F27+Rohini!F27+'Model Town'!F27+'Pacific Mall'!F27 -> 2971472.4 | H30: ='Noida Sec - 18'!G27+'Noida Sec -143'!G27+'Faridabad Sec15'!G27+DLF!G27+'Gurgaon Sec-15'!G27+'Paschim Vihar'!G27+Kalkaji!G27+CP!G27+Rohini!G27+'Model Town'!G27+'Pacific Mall'!G27 -> 2664980.2 | I30: ='Noida Sec - 18'!H27+'Noida Sec -143'!H27+'Faridabad Sec15'!H27+DLF!H27+'Gurgaon Sec-15'!H27+'Paschim Vihar'!H27+Kalkaji!H27+CP!H27+Rohini!H27+'Model Town'!H27+'Pacific Mall'!H27 -> 2748602.5 | J30: ='Noida Sec - 18'!I27+'Noida Sec -143'!I27+'Faridabad Sec15'!I27+DLF!I27+'Gurgaon Sec-15'!I27+'Paschim Vihar'!I27+Kalkaji!I27+CP!I27+Rohini!I27+'Model Town'!I27+'Pacific Mall'!I27 -> 2541424.8 | K30: ='Noida Sec - 18'!J27+'Noida Sec -143'!J27+'Faridabad Sec15'!J27+DLF!J27+'Gurgaon Sec-15'!J27+'Paschim Vihar'!J27+Kalkaji!J27+CP!J27+Rohini!J27+'Model Town'!J27+'Pacific Mall'!J27+'Gurgaon Sec - 10'!J27 -> 2672294.2 | L30: ='Noida Sec - 18'!K27+'Noida Sec -143'!K27+DLF!K27+'Faridabad Sec15'!K27+'Gurgaon Sec-15'!K27+'Gurgaon Sec - 10'!K27+'Paschim Vihar'!K27+Kalkaji!K27+CP!K27+Rohini!K27+'Model Town'!K27+'Pacific Mall'!K27 -> 2729986.8 | M30: ='Noida Sec - 18'!L27+'Noida Sec -143'!L27+DLF!L27+'Faridabad Sec15'!L27+'Gurgaon Sec-15'!L27+'Gurgaon Sec - 10'!L27+'Paschim Vihar'!L27+Kalkaji!L27+CP!L27+Rohini!L27+'Model Town'!L27+'Pacific Mall'!L27 -> 2778963.1 | N30: ='Noida Sec - 18'!M27+'Noida Sec -143'!M27+DLF!M27+'Faridabad Sec15'!M27+'Gurgaon Sec-15'!M27+'Gurgaon Sec - 10'!M27+'Paschim Vihar'!M27+Kalkaji!M27+CP!M27+Rohini!M27+'Model Town'!M27+'Pacific Mall'!M27+'Shalimar Bagh'!M27 -> 3242871.9 | O30: =sum(C30:N30) -> 33423698 | P30: =O30/$O$15 -> 0.17248577 | Q30: =AVERAGE(C30:N30)/11 -> 253209.84
A31: Operating Expenses | C31: =+SUM(C16:C30) -> 17040004 | D31: =+SUM(D16:D30) -> 17270943 | E31: =+SUM(E16:E30) -> 17426834 | F31: =+SUM(F16:F30) -> 17729799 | G31: =+SUM(G16:G30) -> 18135489 | H31: =+SUM(H16:H30) -> 17108218 | I31: =+SUM(I16:I30) -> 16610266 | J31: =+SUM(J16:J30) -> 16313271 | ... N31: =+SUM(N16:N30) -> 19528649 | O31: =sum(C31:N31) -> 2.1029727e+08 | P31: =O31/$O$15 -> 1.0852565 | Q31: =AVERAGE(C31:N31) -> 17524773
A32: Store Level EBITDA | C32: =C15-C31 -> -2337550 | D32: =D15-D31 -> -1473944.9 | E32: =E15-E31 -> -1719586 | F32: =F15-F31 -> -1205458.7 | G32: =G15-G31 -> -1693021.4 | H32: =H15-H31 -> -2307910.6 | I32: =I15-I31 -> -2327658.6 | J32: =J15-J31 -> -2074784.7 | ... N32: =N15-N31 -> 950443.44 | O32: =sum(C32:N32) -> -16520714 | P32: =O32/$O$15 -> -0.085256518 | Q32: =AVERAGE(C32:N32) -> -1376726.2 | S32: 25419194
A33: EBITDA Margin % | C33: =C32/C15 -> -0.15899047 | D33: =D32/D15 -> -0.09330538 | E33: =E32/E15 -> -0.10947723 | F33: =F32/F15 -> -0.072950489 | G33: =G32/G15 -> -0.10296638 | H33: =H32/H15 -> -0.15593667 | I33: =I32/I15 -> -0.16297155 | J33: =J32/J15 -> -0.14571666 | ... N33: =N32/N15 -> 0.046410428 | S33: =O32 -> -16520714
A34: Food Cost | C34: =(C16/C15) -> 0.30497665 | D34: =(D16/D15) -> 0.28457762 | E34: =(E16/E15) -> 0.28879125 | F34: =(F16/F15) -> 0.28678095 | G34: =(G16/G15) -> 0.28498849 | H34: =(H16/H15) -> 0.30287009 | I34: =(I16/I15) -> 0.27808241 | J34: =(J16/J15) -> 0.28036833 | ... N34: =(N16/N15) -> 0.27717627 | S34: =S32+S33 -> 8898479.2
C37: =C32+C30 -> 339714.38 | D37: =D32+D30 -> 1311800.2 | E37: =E32+E30 -> 990328.14 | F37: =F32+F30 -> 1694720 | G37: =G32+G30 -> 1278451 | H37: =H32+H30 -> 357069.61 | I37: =I32+I30 -> 420943.89 | J37: =J32+J30 -> 466640.12 | ... N37: =N32+N30 -> 4193315.4

Sheet Noida Sec - 18
A1: Dosa Coffee - Noida Sector 18 | B1: 45748 | C1: 45778 | D1: 45809 | E1: 45839 | F1: 45870 | G1: 45901 | H1: 45931 | I1: 45962 | J1: 45992 | K1: 46023 | L1: 46054 | M1: 46082 | N1: FY 2025-26
A2: Food Cost Calculation
A3: Opening Stock | B3: 86720 | C3: =B7 -> 80160 | D3: =C7 -> 90114.76 | E3: =D7 -> 88290 | F3: =E7 -> 73436.88 | G3: =F7 -> 76787 | H3: =G7 -> 80448.91 | I3: =H7 -> 77436.86 | J3: =I7 -> 83465.48 | ... M3: =L7 -> 72558 | N3: =+SUM(J3:L3) -> 253855.99
A4: Purchases Food (Less Purchase Return) | B4: 454058.29 | C4: 453168 | D4: 415149 | E4: 471364 | F4: 477271.41 | G4: 426384.89 | H4: 398331 | I4: =398546.35 -> 398546.35 | J4: 396075 | K4: 427467 | L4: =392811.93 -> 392811.93 | M4: 498553 | N4: =sum(B4:M4) -> 5209179.9
A5: Transferred Out | B5: 0 | C5: 0 | D5: 0 | E5: 0 | F5: 0 | G5: 0 | H5: 0 | I5: 0 | J5: 0 | K5: 0 | L5: 0 | M5: 0 | N5: =+SUM(J5:L5) -> 0
